[2024-11-23T01:56:50.349+0000] {local_task_job_runner.py:120} INFO - ::group::Pre task execution logs
[2024-11-23T01:56:50.702+0000] {taskinstance.py:2076} INFO - Dependencies all met for dep_context=non-requeueable deps ti=<TaskInstance: stock_price_prediction.train_model_AAM manual__2024-11-23T01:52:07.286051+00:00 [queued]>
[2024-11-23T01:56:51.097+0000] {taskinstance.py:2076} INFO - Dependencies all met for dep_context=requeueable deps ti=<TaskInstance: stock_price_prediction.train_model_AAM manual__2024-11-23T01:52:07.286051+00:00 [queued]>
[2024-11-23T01:56:51.102+0000] {taskinstance.py:2306} INFO - Starting attempt 1 of 2
[2024-11-23T01:56:51.172+0000] {taskinstance.py:2330} INFO - Executing <Task(PythonOperator): train_model_AAM> on 2024-11-23 01:52:07.286051+00:00
[2024-11-23T01:56:51.198+0000] {logging_mixin.py:188} WARNING - /home/***/.local/lib/python3.12/site-packages/***/task/task_runner/standard_task_runner.py:61 DeprecationWarning: This process (pid=5129) is multi-threaded, use of fork() may lead to deadlocks in the child.
[2024-11-23T01:56:51.202+0000] {standard_task_runner.py:63} INFO - Started process 5135 to run task
[2024-11-23T01:56:51.211+0000] {standard_task_runner.py:90} INFO - Running: ['***', 'tasks', 'run', 'stock_price_prediction', 'train_model_AAM', 'manual__2024-11-23T01:52:07.286051+00:00', '--job-id', '547', '--raw', '--subdir', 'DAGS_FOLDER/stock_price_prediction_dag.py', '--cfg-path', '/tmp/tmp1cmkwcjt']
[2024-11-23T01:56:51.215+0000] {standard_task_runner.py:91} INFO - Job 547: Subtask train_model_AAM
[2024-11-23T01:56:51.522+0000] {task_command.py:426} INFO - Running <TaskInstance: stock_price_prediction.train_model_AAM manual__2024-11-23T01:52:07.286051+00:00 [running]> on host ad983beda88b
[2024-11-23T01:56:52.000+0000] {taskinstance.py:2648} INFO - Exporting env vars: AIRFLOW_CTX_DAG_OWNER='***' AIRFLOW_CTX_DAG_ID='stock_price_prediction' AIRFLOW_CTX_TASK_ID='train_model_AAM' AIRFLOW_CTX_EXECUTION_DATE='2024-11-23T01:52:07.286051+00:00' AIRFLOW_CTX_TRY_NUMBER='1' AIRFLOW_CTX_DAG_RUN_ID='manual__2024-11-23T01:52:07.286051+00:00'
[2024-11-23T01:56:52.006+0000] {taskinstance.py:430} INFO - ::endgroup::
[2024-11-23T01:57:25.885+0000] {logging_mixin.py:188} WARNING - /home/***/.local/lib/python3.12/site-packages/keras/src/layers/convolutional/base_conv.py:107 UserWarning: Do not pass an `input_shape`/`input_dim` argument to a layer. When using Sequential models, prefer using an `Input(shape)` object as the first layer in the model instead.
[2024-11-23T01:57:26.420+0000] {logging_mixin.py:188} INFO - Epoch 1/20
[2024-11-23T01:57:42.049+0000] {logging_mixin.py:188} INFO -  1/77 ━━━━━━━━━━━━━━━━━━━━ 13:38 11s/step - loss: 0.0617
[2024-11-23T01:57:42.298+0000] {logging_mixin.py:188} INFO -  2/77 ━━━━━━━━━━━━━━━━━━━━ 6:03 5s/step - loss: 0.0537
[2024-11-23T01:57:42.390+0000] {logging_mixin.py:188} INFO -  3/77 ━━━━━━━━━━━━━━━━━━━━ 3:12 3s/step - loss: 0.0469
[2024-11-23T01:57:42.521+0000] {logging_mixin.py:188} INFO -  4/77 ━━━━━━━━━━━━━━━━━━━━ 2:09 2s/step - loss: 0.0418
[2024-11-23T01:57:42.826+0000] {logging_mixin.py:188} INFO -  5/77 ━━━━━━━━━━━━━━━━━━━━ 1:41 1s/step - loss: 0.0384
[2024-11-23T01:57:42.914+0000] {logging_mixin.py:188} INFO -  6/77 ━━━━━━━━━━━━━━━━━━━━ 1:21 1s/step - loss: 0.0358
[2024-11-23T01:57:47.810+0000] {logging_mixin.py:188} INFO -  7/77 ━━━━━━━━━━━━━━━━━━━━ 1:23 1s/step - loss: 0.0336
[2024-11-23T01:59:08.733+0000] {logging_mixin.py:188} INFO -  8/77 ━━━━━━━━━━━━━━━━━━━━ 2:41 2s/step - loss: 0.0316
[2024-11-23T01:59:09.012+0000] {logging_mixin.py:188} INFO -  9/77 ━━━━━━━━━━━━━━━━━━━━ 13:00 11s/step - loss: 0.0300
[2024-11-23T01:59:09.619+0000] {logging_mixin.py:188} INFO - 10/77 ━━━━━━━━━━━━━━━━━━━━ 11:28 10s/step - loss: 0.0286
[2024-11-23T01:59:09.852+0000] {logging_mixin.py:188} INFO - 11/77 ━━━━━━━━━━━━━━━━━━━━ 10:11 9s/step - loss: 0.0273 
[2024-11-23T01:59:09.982+0000] {logging_mixin.py:188} INFO - 12/77 ━━━━━━━━━━━━━━━━━━━━ 9:08 8s/step - loss: 0.0262 
[2024-11-23T01:59:10.102+0000] {logging_mixin.py:188} INFO - 13/77 ━━━━━━━━━━━━━━━━━━━━ 8:15 8s/step - loss: 0.0252
[2024-11-23T01:59:10.253+0000] {logging_mixin.py:188} INFO - 15/77 ━━━━━━━━━━━━━━━━━━━━ 6:52 7s/step - loss: 0.0235
[2024-11-23T01:59:10.334+0000] {logging_mixin.py:188} INFO - 16/77 ━━━━━━━━━━━━━━━━━━━━ 6:18 6s/step - loss: 0.0227
[2024-11-23T01:59:10.461+0000] {logging_mixin.py:188} INFO - 17/77 ━━━━━━━━━━━━━━━━━━━━ 5:49 6s/step - loss: 0.0220
[2024-11-23T01:59:10.672+0000] {logging_mixin.py:188} INFO - 18/77 ━━━━━━━━━━━━━━━━━━━━ 5:24 5s/step - loss: 0.0213
[2024-11-23T01:59:10.746+0000] {logging_mixin.py:188} INFO - 20/77 ━━━━━━━━━━━━━━━━━━━━ 4:40 5s/step - loss: 0.0201
[2024-11-23T01:59:10.855+0000] {logging_mixin.py:188} INFO - 21/77 ━━━━━━━━━━━━━━━━━━━━ 4:22 5s/step - loss: 0.0196
[2024-11-23T01:59:10.951+0000] {logging_mixin.py:188} INFO - 24/77 ━━━━━━━━━━━━━━━━━━━━ 3:36 4s/step - loss: 0.0182
[2024-11-23T01:59:11.016+0000] {logging_mixin.py:188} INFO - 25/77 ━━━━━━━━━━━━━━━━━━━━ 3:23 4s/step - loss: 0.0178
[2024-11-23T01:59:11.119+0000] {logging_mixin.py:188} INFO - 27/77 ━━━━━━━━━━━━━━━━━━━━ 3:00 4s/step - loss: 0.0170
[2024-11-23T01:58:45.461+0000] {job.py:218} ERROR - Job heartbeat got an exception
Traceback (most recent call last):
  File "/home/airflow/.local/lib/python3.12/site-packages/sqlalchemy/engine/base.py", line 3371, in _wrap_pool_connect
    return fn()
           ^^^^
  File "/home/airflow/.local/lib/python3.12/site-packages/sqlalchemy/pool/base.py", line 327, in connect
    return _ConnectionFairy._checkout(self)
           ^^^^^^^^^^^^^^^^^^^^^^^^^^^^^^^^
  File "/home/airflow/.local/lib/python3.12/site-packages/sqlalchemy/pool/base.py", line 894, in _checkout
    fairy = _ConnectionRecord.checkout(pool)
            ^^^^^^^^^^^^^^^^^^^^^^^^^^^^^^^^
  File "/home/airflow/.local/lib/python3.12/site-packages/sqlalchemy/pool/base.py", line 493, in checkout
    rec = pool._do_get()
          ^^^^^^^^^^^^^^
  File "/home/airflow/.local/lib/python3.12/site-packages/sqlalchemy/pool/impl.py", line 256, in _do_get
    return self._create_connection()
           ^^^^^^^^^^^^^^^^^^^^^^^^^
  File "/home/airflow/.local/lib/python3.12/site-packages/sqlalchemy/pool/base.py", line 273, in _create_connection
    return _ConnectionRecord(self)
           ^^^^^^^^^^^^^^^^^^^^^^^
  File "/home/airflow/.local/lib/python3.12/site-packages/sqlalchemy/pool/base.py", line 388, in __init__
    self.__connect()
  File "/home/airflow/.local/lib/python3.12/site-packages/sqlalchemy/pool/base.py", line 690, in __connect
    with util.safe_reraise():
  File "/home/airflow/.local/lib/python3.12/site-packages/sqlalchemy/util/langhelpers.py", line 70, in __exit__
    compat.raise_(
  File "/home/airflow/.local/lib/python3.12/site-packages/sqlalchemy/util/compat.py", line 211, in raise_
    raise exception
  File "/home/airflow/.local/lib/python3.12/site-packages/sqlalchemy/pool/base.py", line 686, in __connect
    self.dbapi_connection = connection = pool._invoke_creator(self)
                                         ^^^^^^^^^^^^^^^^^^^^^^^^^^
  File "/home/airflow/.local/lib/python3.12/site-packages/sqlalchemy/engine/create.py", line 574, in connect
    return dialect.connect(*cargs, **cparams)
           ^^^^^^^^^^^^^^^^^^^^^^^^^^^^^^^^^^
  File "/home/airflow/.local/lib/python3.12/site-packages/sqlalchemy/engine/default.py", line 598, in connect
    return self.dbapi.connect(*cargs, **cparams)
           ^^^^^^^^^^^^^^^^^^^^^^^^^^^^^^^^^^^^^
  File "/home/airflow/.local/lib/python3.12/site-packages/psycopg2/__init__.py", line 122, in connect
    conn = _connect(dsn, connection_factory=connection_factory, **kwasync)
           ^^^^^^^^^^^^^^^^^^^^^^^^^^^^^^^^^^^^^^^^^^^^^^^^^^^^^^^^^^^^^^^
psycopg2.OperationalError: could not translate host name "postgres" to address: Temporary failure in name resolution


The above exception was the direct cause of the following exception:

Traceback (most recent call last):
  File "/home/airflow/.local/lib/python3.12/site-packages/airflow/jobs/job.py", line 192, in heartbeat
    self._merge_from(Job._fetch_from_db(self, session))
                     ^^^^^^^^^^^^^^^^^^^^^^^^^^^^^^^^^
  File "/home/airflow/.local/lib/python3.12/site-packages/airflow/api_internal/internal_api_call.py", line 115, in wrapper
    return func(*args, **kwargs)
           ^^^^^^^^^^^^^^^^^^^^^
  File "/home/airflow/.local/lib/python3.12/site-packages/airflow/utils/session.py", line 76, in wrapper
    return func(*args, **kwargs)
           ^^^^^^^^^^^^^^^^^^^^^
  File "/home/airflow/.local/lib/python3.12/site-packages/airflow/utils/retries.py", line 89, in wrapped_function
    for attempt in run_with_db_retries(max_retries=retries, logger=logger, **retry_kwargs):
  File "/home/airflow/.local/lib/python3.12/site-packages/tenacity/__init__.py", line 347, in __iter__
    do = self.iter(retry_state=retry_state)
         ^^^^^^^^^^^^^^^^^^^^^^^^^^^^^^^^^^
  File "/home/airflow/.local/lib/python3.12/site-packages/tenacity/__init__.py", line 325, in iter
    raise retry_exc.reraise()
          ^^^^^^^^^^^^^^^^^^^
  File "/home/airflow/.local/lib/python3.12/site-packages/tenacity/__init__.py", line 158, in reraise
    raise self.last_attempt.result()
          ^^^^^^^^^^^^^^^^^^^^^^^^^^
  File "/usr/local/lib/python3.12/concurrent/futures/_base.py", line 449, in result
    return self.__get_result()
           ^^^^^^^^^^^^^^^^^^^
  File "/usr/local/lib/python3.12/concurrent/futures/_base.py", line 401, in __get_result
    raise self._exception
  File "/home/airflow/.local/lib/python3.12/site-packages/airflow/utils/retries.py", line 98, in wrapped_function
    return func(*args, **kwargs)
           ^^^^^^^^^^^^^^^^^^^^^
  File "/home/airflow/.local/lib/python3.12/site-packages/airflow/jobs/job.py", line 316, in _fetch_from_db
    session.merge(job)
  File "/home/airflow/.local/lib/python3.12/site-packages/sqlalchemy/orm/session.py", line 3056, in merge
    return self._merge(
           ^^^^^^^^^^^^
  File "/home/airflow/.local/lib/python3.12/site-packages/sqlalchemy/orm/session.py", line 3136, in _merge
    merged = self.get(
             ^^^^^^^^^
  File "/home/airflow/.local/lib/python3.12/site-packages/sqlalchemy/orm/session.py", line 2853, in get
    return self._get_impl(
           ^^^^^^^^^^^^^^^
  File "/home/airflow/.local/lib/python3.12/site-packages/sqlalchemy/orm/session.py", line 2975, in _get_impl
    return db_load_fn(
           ^^^^^^^^^^^
  File "/home/airflow/.local/lib/python3.12/site-packages/sqlalchemy/orm/loading.py", line 530, in load_on_pk_identity
    session.execute(
  File "/home/airflow/.local/lib/python3.12/site-packages/sqlalchemy/orm/session.py", line 1716, in execute
    conn = self._connection_for_bind(bind)
           ^^^^^^^^^^^^^^^^^^^^^^^^^^^^^^^
  File "/home/airflow/.local/lib/python3.12/site-packages/sqlalchemy/orm/session.py", line 1555, in _connection_for_bind
    return self._transaction._connection_for_bind(
           ^^^^^^^^^^^^^^^^^^^^^^^^^^^^^^^^^^^^^^^
  File "/home/airflow/.local/lib/python3.12/site-packages/sqlalchemy/orm/session.py", line 750, in _connection_for_bind
    conn = bind.connect()
           ^^^^^^^^^^^^^^
  File "/home/airflow/.local/lib/python3.12/site-packages/sqlalchemy/future/engine.py", line 412, in connect
    return super(Engine, self).connect()
           ^^^^^^^^^^^^^^^^^^^^^^^^^^^^^
  File "/home/airflow/.local/lib/python3.12/site-packages/sqlalchemy/engine/base.py", line 3325, in connect
    return self._connection_cls(self, close_with_result=close_with_result)
           ^^^^^^^^^^^^^^^^^^^^^^^^^^^^^^^^^^^^^^^^^^^^^^^^^^^^^^^^^^^^^^^
  File "/home/airflow/.local/lib/python3.12/site-packages/sqlalchemy/engine/base.py", line 96, in __init__
    else engine.raw_connection()
         ^^^^^^^^^^^^^^^^^^^^^^^
  File "/home/airflow/.local/lib/python3.12/site-packages/sqlalchemy/engine/base.py", line 3404, in raw_connection
    return self._wrap_pool_connect(self.pool.connect, _connection)
           ^^^^^^^^^^^^^^^^^^^^^^^^^^^^^^^^^^^^^^^^^^^^^^^^^^^^^^^
  File "/home/airflow/.local/lib/python3.12/site-packages/sqlalchemy/engine/base.py", line 3374, in _wrap_pool_connect
    Connection._handle_dbapi_exception_noconnection(
  File "/home/airflow/.local/lib/python3.12/site-packages/sqlalchemy/engine/base.py", line 2208, in _handle_dbapi_exception_noconnection
    util.raise_(
  File "/home/airflow/.local/lib/python3.12/site-packages/sqlalchemy/util/compat.py", line 211, in raise_
    raise exception
  File "/home/airflow/.local/lib/python3.12/site-packages/sqlalchemy/engine/base.py", line 3371, in _wrap_pool_connect
    return fn()
           ^^^^
  File "/home/airflow/.local/lib/python3.12/site-packages/sqlalchemy/pool/base.py", line 327, in connect
    return _ConnectionFairy._checkout(self)
           ^^^^^^^^^^^^^^^^^^^^^^^^^^^^^^^^
  File "/home/airflow/.local/lib/python3.12/site-packages/sqlalchemy/pool/base.py", line 894, in _checkout
    fairy = _ConnectionRecord.checkout(pool)
            ^^^^^^^^^^^^^^^^^^^^^^^^^^^^^^^^
  File "/home/airflow/.local/lib/python3.12/site-packages/sqlalchemy/pool/base.py", line 493, in checkout
    rec = pool._do_get()
          ^^^^^^^^^^^^^^
  File "/home/airflow/.local/lib/python3.12/site-packages/sqlalchemy/pool/impl.py", line 256, in _do_get
    return self._create_connection()
           ^^^^^^^^^^^^^^^^^^^^^^^^^
  File "/home/airflow/.local/lib/python3.12/site-packages/sqlalchemy/pool/base.py", line 273, in _create_connection
    return _ConnectionRecord(self)
           ^^^^^^^^^^^^^^^^^^^^^^^
  File "/home/airflow/.local/lib/python3.12/site-packages/sqlalchemy/pool/base.py", line 388, in __init__
    self.__connect()
  File "/home/airflow/.local/lib/python3.12/site-packages/sqlalchemy/pool/base.py", line 690, in __connect
    with util.safe_reraise():
  File "/home/airflow/.local/lib/python3.12/site-packages/sqlalchemy/util/langhelpers.py", line 70, in __exit__
    compat.raise_(
  File "/home/airflow/.local/lib/python3.12/site-packages/sqlalchemy/util/compat.py", line 211, in raise_
    raise exception
  File "/home/airflow/.local/lib/python3.12/site-packages/sqlalchemy/pool/base.py", line 686, in __connect
    self.dbapi_connection = connection = pool._invoke_creator(self)
                                         ^^^^^^^^^^^^^^^^^^^^^^^^^^
  File "/home/airflow/.local/lib/python3.12/site-packages/sqlalchemy/engine/create.py", line 574, in connect
    return dialect.connect(*cargs, **cparams)
           ^^^^^^^^^^^^^^^^^^^^^^^^^^^^^^^^^^
  File "/home/airflow/.local/lib/python3.12/site-packages/sqlalchemy/engine/default.py", line 598, in connect
    return self.dbapi.connect(*cargs, **cparams)
           ^^^^^^^^^^^^^^^^^^^^^^^^^^^^^^^^^^^^^
  File "/home/airflow/.local/lib/python3.12/site-packages/psycopg2/__init__.py", line 122, in connect
    conn = _connect(dsn, connection_factory=connection_factory, **kwasync)
           ^^^^^^^^^^^^^^^^^^^^^^^^^^^^^^^^^^^^^^^^^^^^^^^^^^^^^^^^^^^^^^^
sqlalchemy.exc.OperationalError: (psycopg2.OperationalError) could not translate host name "postgres" to address: Temporary failure in name resolution

(Background on this error at: https://sqlalche.me/e/14/e3q8)
[2024-11-23T01:59:11.151+0000] {job.py:226} ERROR - Job heartbeat failed with error. Scheduler is in unhealthy state
[2024-11-23T01:59:11.225+0000] {logging_mixin.py:188} INFO - 28/77 ━━━━━━━━━━━━━━━━━━━━ 2:50 3s/step - loss: 0.0167
[2024-11-23T01:59:11.279+0000] {logging_mixin.py:188} INFO - 29/77 ━━━━━━━━━━━━━━━━━━━━ 2:41 3s/step - loss: 0.0164
[2024-11-23T01:59:11.740+0000] {logging_mixin.py:188} INFO - 31/77 ━━━━━━━━━━━━━━━━━━━━ 2:24 3s/step - loss: 0.0158
[2024-11-23T01:59:12.677+0000] {logging_mixin.py:188} INFO - 32/77 ━━━━━━━━━━━━━━━━━━━━ 2:17 3s/step - loss: 0.0155
[2024-11-23T01:59:12.722+0000] {logging_mixin.py:188} INFO - 33/77 ━━━━━━━━━━━━━━━━━━━━ 2:11 3s/step - loss: 0.0152
[2024-11-23T01:59:12.769+0000] {logging_mixin.py:188} INFO - 34/77 ━━━━━━━━━━━━━━━━━━━━ 2:04 3s/step - loss: 0.0150
[2024-11-23T01:59:12.841+0000] {logging_mixin.py:188} INFO - 37/77 ━━━━━━━━━━━━━━━━━━━━ 1:46 3s/step - loss: 0.0143
[2024-11-23T01:59:12.920+0000] {logging_mixin.py:188} INFO - 40/77 ━━━━━━━━━━━━━━━━━━━━ 1:30 2s/step - loss: 0.0137
[2024-11-23T01:59:13.453+0000] {logging_mixin.py:188} INFO - 42/77 ━━━━━━━━━━━━━━━━━━━━ 1:21 2s/step - loss: 0.0133
[2024-11-23T01:59:14.203+0000] {logging_mixin.py:188} INFO - 43/77 ━━━━━━━━━━━━━━━━━━━━ 1:18 2s/step - loss: 0.0131
[2024-11-23T01:59:15.182+0000] {logging_mixin.py:188} INFO - 44/77 ━━━━━━━━━━━━━━━━━━━━ 1:15 2s/step - loss: 0.0129
[2024-11-23T01:59:16.532+0000] {logging_mixin.py:188} INFO - 45/77 ━━━━━━━━━━━━━━━━━━━━ 1:11 2s/step - loss: 0.0128
[2024-11-23T01:59:18.050+0000] {logging_mixin.py:188} INFO - 46/77 ━━━━━━━━━━━━━━━━━━━━ 1:09 2s/step - loss: 0.0126
[2024-11-23T02:00:41.599+0000] {job.py:226} ERROR - Job heartbeat failed with error. Scheduler is in unhealthy state
[2024-11-23T02:01:19.420+0000] {logging_mixin.py:188} INFO - 47/77 ━━━━━━━━━━━━━━━━━━━━ 1:09 2s/step - loss: 0.0124
[2024-11-23T02:01:19.667+0000] {logging_mixin.py:188} INFO - 48/77 ━━━━━━━━━━━━━━━━━━━━ 2:17 5s/step - loss: 0.0123
