[2024-11-23T01:56:45.141+0000] {local_task_job_runner.py:120} INFO - ::group::Pre task execution logs
[2024-11-23T01:56:45.627+0000] {taskinstance.py:2076} INFO - Dependencies all met for dep_context=non-requeueable deps ti=<TaskInstance: stock_price_prediction.train_model_BHG manual__2024-11-23T01:52:07.286051+00:00 [queued]>
[2024-11-23T01:56:46.067+0000] {taskinstance.py:2076} INFO - Dependencies all met for dep_context=requeueable deps ti=<TaskInstance: stock_price_prediction.train_model_BHG manual__2024-11-23T01:52:07.286051+00:00 [queued]>
[2024-11-23T01:56:46.084+0000] {taskinstance.py:2306} INFO - Starting attempt 1 of 2
[2024-11-23T01:56:46.231+0000] {taskinstance.py:2330} INFO - Executing <Task(PythonOperator): train_model_BHG> on 2024-11-23 01:52:07.286051+00:00
[2024-11-23T01:56:46.338+0000] {logging_mixin.py:188} WARNING - /home/***/.local/lib/python3.12/site-packages/***/task/task_runner/standard_task_runner.py:61 DeprecationWarning: This process (pid=5051) is multi-threaded, use of fork() may lead to deadlocks in the child.
[2024-11-23T01:56:46.324+0000] {standard_task_runner.py:90} INFO - Running: ['***', 'tasks', 'run', 'stock_price_prediction', 'train_model_BHG', 'manual__2024-11-23T01:52:07.286051+00:00', '--job-id', '540', '--raw', '--subdir', 'DAGS_FOLDER/stock_price_prediction_dag.py', '--cfg-path', '/tmp/tmpoetviyvp']
[2024-11-23T01:56:46.347+0000] {standard_task_runner.py:91} INFO - Job 540: Subtask train_model_BHG
[2024-11-23T01:56:46.354+0000] {standard_task_runner.py:63} INFO - Started process 5091 to run task
[2024-11-23T01:56:46.503+0000] {task_command.py:426} INFO - Running <TaskInstance: stock_price_prediction.train_model_BHG manual__2024-11-23T01:52:07.286051+00:00 [running]> on host ad983beda88b
[2024-11-23T01:56:46.865+0000] {taskinstance.py:2648} INFO - Exporting env vars: AIRFLOW_CTX_DAG_OWNER='***' AIRFLOW_CTX_DAG_ID='stock_price_prediction' AIRFLOW_CTX_TASK_ID='train_model_BHG' AIRFLOW_CTX_EXECUTION_DATE='2024-11-23T01:52:07.286051+00:00' AIRFLOW_CTX_TRY_NUMBER='1' AIRFLOW_CTX_DAG_RUN_ID='manual__2024-11-23T01:52:07.286051+00:00'
[2024-11-23T01:56:46.869+0000] {taskinstance.py:430} INFO - ::endgroup::
[2024-11-23T01:57:23.384+0000] {logging_mixin.py:188} WARNING - /home/***/.local/lib/python3.12/site-packages/keras/src/layers/convolutional/base_conv.py:107 UserWarning: Do not pass an `input_shape`/`input_dim` argument to a layer. When using Sequential models, prefer using an `Input(shape)` object as the first layer in the model instead.
[2024-11-23T01:57:25.838+0000] {logging_mixin.py:188} INFO - Epoch 1/20
[2024-11-23T01:57:32.959+0000] {logging_mixin.py:188} INFO -  1/16 ━━━━━━━━━━━━━━━━━━━━ 1:46 7s/step - loss: 0.5200
[2024-11-23T01:57:33.095+0000] {logging_mixin.py:188} INFO -  2/16 ━━━━━━━━━━━━━━━━━━━━ 1s 115ms/step - loss: 0.4911
[2024-11-23T01:57:33.118+0000] {logging_mixin.py:188} INFO -  3/16 ━━━━━━━━━━━━━━━━━━━━ 1s 92ms/step - loss: 0.4500 
[2024-11-23T01:57:33.263+0000] {logging_mixin.py:188} INFO -  4/16 ━━━━━━━━━━━━━━━━━━━━ 1s 86ms/step - loss: 0.4160
[2024-11-23T01:57:33.300+0000] {logging_mixin.py:188} INFO -  5/16 ━━━━━━━━━━━━━━━━━━━━ 1s 91ms/step - loss: 0.3844
[2024-11-23T01:57:33.385+0000] {logging_mixin.py:188} INFO -  6/16 ━━━━━━━━━━━━━━━━━━━━ 0s 89ms/step - loss: 0.3575
[2024-11-23T01:57:33.435+0000] {logging_mixin.py:188} INFO -  7/16 ━━━━━━━━━━━━━━━━━━━━ 0s 84ms/step - loss: 0.3362
[2024-11-23T01:57:33.508+0000] {logging_mixin.py:188} INFO -  8/16 ━━━━━━━━━━━━━━━━━━━━ 0s 82ms/step - loss: 0.3188
[2024-11-23T01:57:33.613+0000] {logging_mixin.py:188} INFO -  9/16 ━━━━━━━━━━━━━━━━━━━━ 0s 85ms/step - loss: 0.3033
[2024-11-23T01:57:33.724+0000] {logging_mixin.py:188} INFO - 10/16 ━━━━━━━━━━━━━━━━━━━━ 0s 88ms/step - loss: 0.2896
[2024-11-23T01:57:33.858+0000] {logging_mixin.py:188} INFO - 11/16 ━━━━━━━━━━━━━━━━━━━━ 0s 92ms/step - loss: 0.2774
[2024-11-23T01:57:34.154+0000] {logging_mixin.py:188} INFO - 12/16 ━━━━━━━━━━━━━━━━━━━━ 0s 93ms/step - loss: 0.2663
[2024-11-23T01:57:34.486+0000] {logging_mixin.py:188} INFO - 13/16 ━━━━━━━━━━━━━━━━━━━━ 0s 108ms/step - loss: 0.2561
[2024-11-23T01:57:35.058+0000] {logging_mixin.py:188} INFO - 14/16 ━━━━━━━━━━━━━━━━━━━━ 0s 146ms/step - loss: 0.2470
[2024-11-23T01:57:41.826+0000] {logging_mixin.py:188} INFO - 15/16 ━━━━━━━━━━━━━━━━━━━━ 0s 230ms/step - loss: 0.2386
[2024-11-23T01:57:41.856+0000] {logging_mixin.py:188} INFO - 16/16 ━━━━━━━━━━━━━━━━━━━━ 0s 595ms/step - loss: 0.2312
[2024-11-23T01:57:41.920+0000] {logging_mixin.py:188} INFO - 16/16 ━━━━━━━━━━━━━━━━━━━━ 16s 599ms/step - loss: 0.2247
[2024-11-23T01:57:41.922+0000] {logging_mixin.py:188} INFO - Epoch 2/20
[2024-11-23T01:57:42.302+0000] {logging_mixin.py:188} INFO -  1/16 ━━━━━━━━━━━━━━━━━━━━ 5s 378ms/step - loss: 0.0088
[2024-11-23T01:57:42.461+0000] {logging_mixin.py:188} INFO -  3/16 ━━━━━━━━━━━━━━━━━━━━ 1s 80ms/step - loss: 0.0097 
[2024-11-23T01:57:42.650+0000] {logging_mixin.py:188} INFO -  4/16 ━━━━━━━━━━━━━━━━━━━━ 1s 116ms/step - loss: 0.0114
[2024-11-23T01:57:42.731+0000] {logging_mixin.py:188} INFO -  5/16 ━━━━━━━━━━━━━━━━━━━━ 1s 107ms/step - loss: 0.0125
[2024-11-23T01:57:44.020+0000] {logging_mixin.py:188} INFO -  7/16 ━━━━━━━━━━━━━━━━━━━━ 0s 106ms/step - loss: 0.0139
[2024-11-23T01:57:51.576+0000] {logging_mixin.py:188} INFO -  8/16 ━━━━━━━━━━━━━━━━━━━━ 3s 379ms/step - loss: 0.0142
[2024-11-23T01:59:08.732+0000] {logging_mixin.py:188} INFO -  9/16 ━━━━━━━━━━━━━━━━━━━━ 45s 7s/step - loss: 0.0148  
[2024-11-23T01:59:09.135+0000] {logging_mixin.py:188} INFO - 10/16 ━━━━━━━━━━━━━━━━━━━━ 57s 10s/step - loss: 0.0153
[2024-11-23T01:59:09.324+0000] {logging_mixin.py:188} INFO - 11/16 ━━━━━━━━━━━━━━━━━━━━ 43s 9s/step - loss: 0.0155 
[2024-11-23T01:59:09.651+0000] {logging_mixin.py:188} INFO - 12/16 ━━━━━━━━━━━━━━━━━━━━ 31s 8s/step - loss: 0.0159
[2024-11-23T01:59:09.835+0000] {logging_mixin.py:188} INFO - 13/16 ━━━━━━━━━━━━━━━━━━━━ 21s 7s/step - loss: 0.0162
[2024-11-23T01:59:10.000+0000] {logging_mixin.py:188} INFO - 14/16 ━━━━━━━━━━━━━━━━━━━━ 13s 7s/step - loss: 0.0164
[2024-11-23T01:59:10.220+0000] {logging_mixin.py:188} INFO - 15/16 ━━━━━━━━━━━━━━━━━━━━ 6s 6s/step - loss: 0.0166 
[2024-11-23T01:59:10.284+0000] {logging_mixin.py:188} INFO - 16/16 ━━━━━━━━━━━━━━━━━━━━ 88s 6s/step - loss: 0.0167
[2024-11-23T01:59:10.302+0000] {logging_mixin.py:188} INFO - Epoch 3/20
[2024-11-23T01:58:53.739+0000] {job.py:218} ERROR - Job heartbeat got an exception
Traceback (most recent call last):
  File "/home/airflow/.local/lib/python3.12/site-packages/sqlalchemy/engine/base.py", line 3371, in _wrap_pool_connect
    return fn()
           ^^^^
  File "/home/airflow/.local/lib/python3.12/site-packages/sqlalchemy/pool/base.py", line 327, in connect
    return _ConnectionFairy._checkout(self)
           ^^^^^^^^^^^^^^^^^^^^^^^^^^^^^^^^
  File "/home/airflow/.local/lib/python3.12/site-packages/sqlalchemy/pool/base.py", line 894, in _checkout
    fairy = _ConnectionRecord.checkout(pool)
            ^^^^^^^^^^^^^^^^^^^^^^^^^^^^^^^^
  File "/home/airflow/.local/lib/python3.12/site-packages/sqlalchemy/pool/base.py", line 493, in checkout
    rec = pool._do_get()
          ^^^^^^^^^^^^^^
  File "/home/airflow/.local/lib/python3.12/site-packages/sqlalchemy/pool/impl.py", line 256, in _do_get
    return self._create_connection()
           ^^^^^^^^^^^^^^^^^^^^^^^^^
  File "/home/airflow/.local/lib/python3.12/site-packages/sqlalchemy/pool/base.py", line 273, in _create_connection
    return _ConnectionRecord(self)
           ^^^^^^^^^^^^^^^^^^^^^^^
  File "/home/airflow/.local/lib/python3.12/site-packages/sqlalchemy/pool/base.py", line 388, in __init__
    self.__connect()
  File "/home/airflow/.local/lib/python3.12/site-packages/sqlalchemy/pool/base.py", line 690, in __connect
    with util.safe_reraise():
  File "/home/airflow/.local/lib/python3.12/site-packages/sqlalchemy/util/langhelpers.py", line 70, in __exit__
    compat.raise_(
  File "/home/airflow/.local/lib/python3.12/site-packages/sqlalchemy/util/compat.py", line 211, in raise_
    raise exception
  File "/home/airflow/.local/lib/python3.12/site-packages/sqlalchemy/pool/base.py", line 686, in __connect
    self.dbapi_connection = connection = pool._invoke_creator(self)
                                         ^^^^^^^^^^^^^^^^^^^^^^^^^^
  File "/home/airflow/.local/lib/python3.12/site-packages/sqlalchemy/engine/create.py", line 574, in connect
    return dialect.connect(*cargs, **cparams)
           ^^^^^^^^^^^^^^^^^^^^^^^^^^^^^^^^^^
  File "/home/airflow/.local/lib/python3.12/site-packages/sqlalchemy/engine/default.py", line 598, in connect
    return self.dbapi.connect(*cargs, **cparams)
           ^^^^^^^^^^^^^^^^^^^^^^^^^^^^^^^^^^^^^
  File "/home/airflow/.local/lib/python3.12/site-packages/psycopg2/__init__.py", line 122, in connect
    conn = _connect(dsn, connection_factory=connection_factory, **kwasync)
           ^^^^^^^^^^^^^^^^^^^^^^^^^^^^^^^^^^^^^^^^^^^^^^^^^^^^^^^^^^^^^^^
psycopg2.OperationalError: could not translate host name "postgres" to address: Temporary failure in name resolution


The above exception was the direct cause of the following exception:

Traceback (most recent call last):
  File "/home/airflow/.local/lib/python3.12/site-packages/airflow/jobs/job.py", line 192, in heartbeat
    self._merge_from(Job._fetch_from_db(self, session))
                     ^^^^^^^^^^^^^^^^^^^^^^^^^^^^^^^^^
  File "/home/airflow/.local/lib/python3.12/site-packages/airflow/api_internal/internal_api_call.py", line 115, in wrapper
    return func(*args, **kwargs)
           ^^^^^^^^^^^^^^^^^^^^^
  File "/home/airflow/.local/lib/python3.12/site-packages/airflow/utils/session.py", line 76, in wrapper
    return func(*args, **kwargs)
           ^^^^^^^^^^^^^^^^^^^^^
  File "/home/airflow/.local/lib/python3.12/site-packages/airflow/utils/retries.py", line 89, in wrapped_function
    for attempt in run_with_db_retries(max_retries=retries, logger=logger, **retry_kwargs):
  File "/home/airflow/.local/lib/python3.12/site-packages/tenacity/__init__.py", line 347, in __iter__
    do = self.iter(retry_state=retry_state)
         ^^^^^^^^^^^^^^^^^^^^^^^^^^^^^^^^^^
  File "/home/airflow/.local/lib/python3.12/site-packages/tenacity/__init__.py", line 325, in iter
    raise retry_exc.reraise()
          ^^^^^^^^^^^^^^^^^^^
  File "/home/airflow/.local/lib/python3.12/site-packages/tenacity/__init__.py", line 158, in reraise
    raise self.last_attempt.result()
          ^^^^^^^^^^^^^^^^^^^^^^^^^^
  File "/usr/local/lib/python3.12/concurrent/futures/_base.py", line 449, in result
    return self.__get_result()
           ^^^^^^^^^^^^^^^^^^^
  File "/usr/local/lib/python3.12/concurrent/futures/_base.py", line 401, in __get_result
    raise self._exception
  File "/home/airflow/.local/lib/python3.12/site-packages/airflow/utils/retries.py", line 98, in wrapped_function
    return func(*args, **kwargs)
           ^^^^^^^^^^^^^^^^^^^^^
  File "/home/airflow/.local/lib/python3.12/site-packages/airflow/jobs/job.py", line 316, in _fetch_from_db
    session.merge(job)
  File "/home/airflow/.local/lib/python3.12/site-packages/sqlalchemy/orm/session.py", line 3056, in merge
    return self._merge(
           ^^^^^^^^^^^^
  File "/home/airflow/.local/lib/python3.12/site-packages/sqlalchemy/orm/session.py", line 3136, in _merge
    merged = self.get(
             ^^^^^^^^^
  File "/home/airflow/.local/lib/python3.12/site-packages/sqlalchemy/orm/session.py", line 2853, in get
    return self._get_impl(
           ^^^^^^^^^^^^^^^
  File "/home/airflow/.local/lib/python3.12/site-packages/sqlalchemy/orm/session.py", line 2975, in _get_impl
    return db_load_fn(
           ^^^^^^^^^^^
  File "/home/airflow/.local/lib/python3.12/site-packages/sqlalchemy/orm/loading.py", line 530, in load_on_pk_identity
    session.execute(
  File "/home/airflow/.local/lib/python3.12/site-packages/sqlalchemy/orm/session.py", line 1716, in execute
    conn = self._connection_for_bind(bind)
           ^^^^^^^^^^^^^^^^^^^^^^^^^^^^^^^
  File "/home/airflow/.local/lib/python3.12/site-packages/sqlalchemy/orm/session.py", line 1555, in _connection_for_bind
    return self._transaction._connection_for_bind(
           ^^^^^^^^^^^^^^^^^^^^^^^^^^^^^^^^^^^^^^^
  File "/home/airflow/.local/lib/python3.12/site-packages/sqlalchemy/orm/session.py", line 750, in _connection_for_bind
    conn = bind.connect()
           ^^^^^^^^^^^^^^
  File "/home/airflow/.local/lib/python3.12/site-packages/sqlalchemy/future/engine.py", line 412, in connect
    return super(Engine, self).connect()
           ^^^^^^^^^^^^^^^^^^^^^^^^^^^^^
  File "/home/airflow/.local/lib/python3.12/site-packages/sqlalchemy/engine/base.py", line 3325, in connect
    return self._connection_cls(self, close_with_result=close_with_result)
           ^^^^^^^^^^^^^^^^^^^^^^^^^^^^^^^^^^^^^^^^^^^^^^^^^^^^^^^^^^^^^^^
  File "/home/airflow/.local/lib/python3.12/site-packages/sqlalchemy/engine/base.py", line 96, in __init__
    else engine.raw_connection()
         ^^^^^^^^^^^^^^^^^^^^^^^
  File "/home/airflow/.local/lib/python3.12/site-packages/sqlalchemy/engine/base.py", line 3404, in raw_connection
    return self._wrap_pool_connect(self.pool.connect, _connection)
           ^^^^^^^^^^^^^^^^^^^^^^^^^^^^^^^^^^^^^^^^^^^^^^^^^^^^^^^
  File "/home/airflow/.local/lib/python3.12/site-packages/sqlalchemy/engine/base.py", line 3374, in _wrap_pool_connect
    Connection._handle_dbapi_exception_noconnection(
  File "/home/airflow/.local/lib/python3.12/site-packages/sqlalchemy/engine/base.py", line 2208, in _handle_dbapi_exception_noconnection
    util.raise_(
  File "/home/airflow/.local/lib/python3.12/site-packages/sqlalchemy/util/compat.py", line 211, in raise_
    raise exception
  File "/home/airflow/.local/lib/python3.12/site-packages/sqlalchemy/engine/base.py", line 3371, in _wrap_pool_connect
    return fn()
           ^^^^
  File "/home/airflow/.local/lib/python3.12/site-packages/sqlalchemy/pool/base.py", line 327, in connect
    return _ConnectionFairy._checkout(self)
           ^^^^^^^^^^^^^^^^^^^^^^^^^^^^^^^^
  File "/home/airflow/.local/lib/python3.12/site-packages/sqlalchemy/pool/base.py", line 894, in _checkout
    fairy = _ConnectionRecord.checkout(pool)
            ^^^^^^^^^^^^^^^^^^^^^^^^^^^^^^^^
  File "/home/airflow/.local/lib/python3.12/site-packages/sqlalchemy/pool/base.py", line 493, in checkout
    rec = pool._do_get()
          ^^^^^^^^^^^^^^
  File "/home/airflow/.local/lib/python3.12/site-packages/sqlalchemy/pool/impl.py", line 256, in _do_get
    return self._create_connection()
           ^^^^^^^^^^^^^^^^^^^^^^^^^
  File "/home/airflow/.local/lib/python3.12/site-packages/sqlalchemy/pool/base.py", line 273, in _create_connection
    return _ConnectionRecord(self)
           ^^^^^^^^^^^^^^^^^^^^^^^
  File "/home/airflow/.local/lib/python3.12/site-packages/sqlalchemy/pool/base.py", line 388, in __init__
    self.__connect()
  File "/home/airflow/.local/lib/python3.12/site-packages/sqlalchemy/pool/base.py", line 690, in __connect
    with util.safe_reraise():
  File "/home/airflow/.local/lib/python3.12/site-packages/sqlalchemy/util/langhelpers.py", line 70, in __exit__
    compat.raise_(
  File "/home/airflow/.local/lib/python3.12/site-packages/sqlalchemy/util/compat.py", line 211, in raise_
    raise exception
  File "/home/airflow/.local/lib/python3.12/site-packages/sqlalchemy/pool/base.py", line 686, in __connect
    self.dbapi_connection = connection = pool._invoke_creator(self)
                                         ^^^^^^^^^^^^^^^^^^^^^^^^^^
  File "/home/airflow/.local/lib/python3.12/site-packages/sqlalchemy/engine/create.py", line 574, in connect
    return dialect.connect(*cargs, **cparams)
           ^^^^^^^^^^^^^^^^^^^^^^^^^^^^^^^^^^
  File "/home/airflow/.local/lib/python3.12/site-packages/sqlalchemy/engine/default.py", line 598, in connect
    return self.dbapi.connect(*cargs, **cparams)
           ^^^^^^^^^^^^^^^^^^^^^^^^^^^^^^^^^^^^^
  File "/home/airflow/.local/lib/python3.12/site-packages/psycopg2/__init__.py", line 122, in connect
    conn = _connect(dsn, connection_factory=connection_factory, **kwasync)
           ^^^^^^^^^^^^^^^^^^^^^^^^^^^^^^^^^^^^^^^^^^^^^^^^^^^^^^^^^^^^^^^
sqlalchemy.exc.OperationalError: (psycopg2.OperationalError) could not translate host name "postgres" to address: Temporary failure in name resolution

(Background on this error at: https://sqlalche.me/e/14/e3q8)
[2024-11-23T01:59:11.427+0000] {job.py:226} ERROR - Job heartbeat failed with error. Scheduler is in unhealthy state
[2024-11-23T02:00:55.717+0000] {job.py:226} ERROR - Job heartbeat failed with error. Scheduler is in unhealthy state
