[2024-11-23T01:56:45.751+0000] {local_task_job_runner.py:120} INFO - ::group::Pre task execution logs
[2024-11-23T01:56:46.222+0000] {taskinstance.py:2076} INFO - Dependencies all met for dep_context=non-requeueable deps ti=<TaskInstance: stock_price_prediction.train_model_C22 manual__2024-11-23T01:52:07.286051+00:00 [queued]>
[2024-11-23T01:56:46.636+0000] {taskinstance.py:2076} INFO - Dependencies all met for dep_context=requeueable deps ti=<TaskInstance: stock_price_prediction.train_model_C22 manual__2024-11-23T01:52:07.286051+00:00 [queued]>
[2024-11-23T01:56:46.644+0000] {taskinstance.py:2306} INFO - Starting attempt 1 of 2
[2024-11-23T01:56:46.719+0000] {taskinstance.py:2330} INFO - Executing <Task(PythonOperator): train_model_C22> on 2024-11-23 01:52:07.286051+00:00
[2024-11-23T01:56:46.770+0000] {standard_task_runner.py:90} INFO - Running: ['***', 'tasks', 'run', 'stock_price_prediction', 'train_model_C22', 'manual__2024-11-23T01:52:07.286051+00:00', '--job-id', '546', '--raw', '--subdir', 'DAGS_FOLDER/stock_price_prediction_dag.py', '--cfg-path', '/tmp/tmppe45h74e']
[2024-11-23T01:56:46.774+0000] {standard_task_runner.py:91} INFO - Job 546: Subtask train_model_C22
[2024-11-23T01:56:46.760+0000] {logging_mixin.py:188} WARNING - /home/***/.local/lib/python3.12/site-packages/***/task/task_runner/standard_task_runner.py:61 DeprecationWarning: This process (pid=5049) is multi-threaded, use of fork() may lead to deadlocks in the child.
[2024-11-23T01:56:46.786+0000] {standard_task_runner.py:63} INFO - Started process 5128 to run task
[2024-11-23T01:56:46.932+0000] {task_command.py:426} INFO - Running <TaskInstance: stock_price_prediction.train_model_C22 manual__2024-11-23T01:52:07.286051+00:00 [running]> on host ad983beda88b
[2024-11-23T01:56:47.465+0000] {taskinstance.py:2648} INFO - Exporting env vars: AIRFLOW_CTX_DAG_OWNER='***' AIRFLOW_CTX_DAG_ID='stock_price_prediction' AIRFLOW_CTX_TASK_ID='train_model_C22' AIRFLOW_CTX_EXECUTION_DATE='2024-11-23T01:52:07.286051+00:00' AIRFLOW_CTX_TRY_NUMBER='1' AIRFLOW_CTX_DAG_RUN_ID='manual__2024-11-23T01:52:07.286051+00:00'
[2024-11-23T01:56:47.472+0000] {taskinstance.py:430} INFO - ::endgroup::
[2024-11-23T01:57:23.370+0000] {logging_mixin.py:188} WARNING - /home/***/.local/lib/python3.12/site-packages/keras/src/layers/convolutional/base_conv.py:107 UserWarning: Do not pass an `input_shape`/`input_dim` argument to a layer. When using Sequential models, prefer using an `Input(shape)` object as the first layer in the model instead.
[2024-11-23T01:57:24.127+0000] {logging_mixin.py:188} INFO - Epoch 1/20
[2024-11-23T01:57:32.597+0000] {logging_mixin.py:188} INFO -  1/20 ━━━━━━━━━━━━━━━━━━━━ 2:39 8s/step - loss: 0.2675
[2024-11-23T01:57:32.613+0000] {logging_mixin.py:188} INFO -  2/20 ━━━━━━━━━━━━━━━━━━━━ 1s 107ms/step - loss: 0.2298
[2024-11-23T01:57:32.728+0000] {logging_mixin.py:188} INFO -  3/20 ━━━━━━━━━━━━━━━━━━━━ 1s 111ms/step - loss: 0.1996
[2024-11-23T01:57:32.837+0000] {logging_mixin.py:188} INFO -  4/20 ━━━━━━━━━━━━━━━━━━━━ 1s 107ms/step - loss: 0.1779
[2024-11-23T01:57:32.926+0000] {logging_mixin.py:188} INFO -  6/20 ━━━━━━━━━━━━━━━━━━━━ 1s 84ms/step - loss: 0.1533 
[2024-11-23T01:57:32.986+0000] {logging_mixin.py:188} INFO -  7/20 ━━━━━━━━━━━━━━━━━━━━ 1s 80ms/step - loss: 0.1445
[2024-11-23T01:57:33.060+0000] {logging_mixin.py:188} INFO -  9/20 ━━━━━━━━━━━━━━━━━━━━ 0s 69ms/step - loss: 0.1300
[2024-11-23T01:57:33.133+0000] {logging_mixin.py:188} INFO - 11/20 ━━━━━━━━━━━━━━━━━━━━ 0s 63ms/step - loss: 0.1194
[2024-11-23T01:57:33.215+0000] {logging_mixin.py:188} INFO - 12/20 ━━━━━━━━━━━━━━━━━━━━ 0s 64ms/step - loss: 0.1150
[2024-11-23T01:57:33.350+0000] {logging_mixin.py:188} INFO - 13/20 ━━━━━━━━━━━━━━━━━━━━ 0s 70ms/step - loss: 0.1111
[2024-11-23T01:57:33.447+0000] {logging_mixin.py:188} INFO - 15/20 ━━━━━━━━━━━━━━━━━━━━ 0s 67ms/step - loss: 0.1044
[2024-11-23T01:57:33.536+0000] {logging_mixin.py:188} INFO - 17/20 ━━━━━━━━━━━━━━━━━━━━ 0s 64ms/step - loss: 0.0988
[2024-11-23T01:57:33.602+0000] {logging_mixin.py:188} INFO - 19/20 ━━━━━━━━━━━━━━━━━━━━ 0s 61ms/step - loss: 0.0939
[2024-11-23T01:57:33.646+0000] {logging_mixin.py:188} INFO - 20/20 ━━━━━━━━━━━━━━━━━━━━ 10s 60ms/step - loss: 0.0898
[2024-11-23T01:57:33.672+0000] {logging_mixin.py:188} INFO - Epoch 2/20
[2024-11-23T01:57:41.826+0000] {logging_mixin.py:188} INFO -  1/20 ━━━━━━━━━━━━━━━━━━━━ 44s 2s/step - loss: 0.0085
[2024-11-23T01:57:41.858+0000] {logging_mixin.py:188} INFO -  2/20 ━━━━━━━━━━━━━━━━━━━━ 1:45 6s/step - loss: 0.0115
[2024-11-23T01:57:42.045+0000] {logging_mixin.py:188} INFO -  3/20 ━━━━━━━━━━━━━━━━━━━━ 51s 3s/step - loss: 0.0130 
[2024-11-23T01:57:42.088+0000] {logging_mixin.py:188} INFO -  4/20 ━━━━━━━━━━━━━━━━━━━━ 32s 2s/step - loss: 0.0136
[2024-11-23T01:57:42.143+0000] {logging_mixin.py:188} INFO -  5/20 ━━━━━━━━━━━━━━━━━━━━ 22s 2s/step - loss: 0.0138
[2024-11-23T01:57:42.263+0000] {logging_mixin.py:188} INFO -  7/20 ━━━━━━━━━━━━━━━━━━━━ 13s 1s/step - loss: 0.0141
[2024-11-23T01:57:42.370+0000] {logging_mixin.py:188} INFO -  9/20 ━━━━━━━━━━━━━━━━━━━━ 8s 794ms/step - loss: 0.0144
[2024-11-23T01:57:42.463+0000] {logging_mixin.py:188} INFO - 10/20 ━━━━━━━━━━━━━━━━━━━━ 7s 716ms/step - loss: 0.0144
[2024-11-23T01:57:42.560+0000] {logging_mixin.py:188} INFO - 12/20 ━━━━━━━━━━━━━━━━━━━━ 4s 594ms/step - loss: 0.0145
[2024-11-23T01:57:42.682+0000] {logging_mixin.py:188} INFO - 14/20 ━━━━━━━━━━━━━━━━━━━━ 3s 513ms/step - loss: 0.0145
[2024-11-23T01:57:42.756+0000] {logging_mixin.py:188} INFO - 16/20 ━━━━━━━━━━━━━━━━━━━━ 1s 449ms/step - loss: 0.0145
[2024-11-23T01:57:42.828+0000] {logging_mixin.py:188} INFO - 18/20 ━━━━━━━━━━━━━━━━━━━━ 0s 401ms/step - loss: 0.0145
[2024-11-23T01:57:42.909+0000] {logging_mixin.py:188} INFO - 19/20 ━━━━━━━━━━━━━━━━━━━━ 0s 383ms/step - loss: 0.0145
[2024-11-23T01:57:44.856+0000] {logging_mixin.py:188} INFO - 20/20 ━━━━━━━━━━━━━━━━━━━━ 0s 378ms/step - loss: 0.0144
[2024-11-23T01:57:49.332+0000] {logging_mixin.py:188} INFO - 20/20 ━━━━━━━━━━━━━━━━━━━━ 11s 475ms/step - loss: 0.0144
[2024-11-23T01:57:57.305+0000] {logging_mixin.py:188} INFO - Epoch 3/20
[2024-11-23T01:58:34.410+0000] {job.py:218} ERROR - Job heartbeat got an exception
Traceback (most recent call last):
  File "/home/airflow/.local/lib/python3.12/site-packages/sqlalchemy/engine/base.py", line 3371, in _wrap_pool_connect
    return fn()
           ^^^^
  File "/home/airflow/.local/lib/python3.12/site-packages/sqlalchemy/pool/base.py", line 327, in connect
    return _ConnectionFairy._checkout(self)
           ^^^^^^^^^^^^^^^^^^^^^^^^^^^^^^^^
  File "/home/airflow/.local/lib/python3.12/site-packages/sqlalchemy/pool/base.py", line 894, in _checkout
    fairy = _ConnectionRecord.checkout(pool)
            ^^^^^^^^^^^^^^^^^^^^^^^^^^^^^^^^
  File "/home/airflow/.local/lib/python3.12/site-packages/sqlalchemy/pool/base.py", line 493, in checkout
    rec = pool._do_get()
          ^^^^^^^^^^^^^^
  File "/home/airflow/.local/lib/python3.12/site-packages/sqlalchemy/pool/impl.py", line 256, in _do_get
    return self._create_connection()
           ^^^^^^^^^^^^^^^^^^^^^^^^^
  File "/home/airflow/.local/lib/python3.12/site-packages/sqlalchemy/pool/base.py", line 273, in _create_connection
    return _ConnectionRecord(self)
           ^^^^^^^^^^^^^^^^^^^^^^^
  File "/home/airflow/.local/lib/python3.12/site-packages/sqlalchemy/pool/base.py", line 388, in __init__
    self.__connect()
  File "/home/airflow/.local/lib/python3.12/site-packages/sqlalchemy/pool/base.py", line 690, in __connect
    with util.safe_reraise():
  File "/home/airflow/.local/lib/python3.12/site-packages/sqlalchemy/util/langhelpers.py", line 70, in __exit__
    compat.raise_(
  File "/home/airflow/.local/lib/python3.12/site-packages/sqlalchemy/util/compat.py", line 211, in raise_
    raise exception
  File "/home/airflow/.local/lib/python3.12/site-packages/sqlalchemy/pool/base.py", line 686, in __connect
    self.dbapi_connection = connection = pool._invoke_creator(self)
                                         ^^^^^^^^^^^^^^^^^^^^^^^^^^
  File "/home/airflow/.local/lib/python3.12/site-packages/sqlalchemy/engine/create.py", line 574, in connect
    return dialect.connect(*cargs, **cparams)
           ^^^^^^^^^^^^^^^^^^^^^^^^^^^^^^^^^^
  File "/home/airflow/.local/lib/python3.12/site-packages/sqlalchemy/engine/default.py", line 598, in connect
    return self.dbapi.connect(*cargs, **cparams)
           ^^^^^^^^^^^^^^^^^^^^^^^^^^^^^^^^^^^^^
  File "/home/airflow/.local/lib/python3.12/site-packages/psycopg2/__init__.py", line 122, in connect
    conn = _connect(dsn, connection_factory=connection_factory, **kwasync)
           ^^^^^^^^^^^^^^^^^^^^^^^^^^^^^^^^^^^^^^^^^^^^^^^^^^^^^^^^^^^^^^^
psycopg2.OperationalError: could not translate host name "postgres" to address: Temporary failure in name resolution


The above exception was the direct cause of the following exception:

Traceback (most recent call last):
  File "/home/airflow/.local/lib/python3.12/site-packages/airflow/jobs/job.py", line 192, in heartbeat
    self._merge_from(Job._fetch_from_db(self, session))
                     ^^^^^^^^^^^^^^^^^^^^^^^^^^^^^^^^^
  File "/home/airflow/.local/lib/python3.12/site-packages/airflow/api_internal/internal_api_call.py", line 115, in wrapper
    return func(*args, **kwargs)
           ^^^^^^^^^^^^^^^^^^^^^
  File "/home/airflow/.local/lib/python3.12/site-packages/airflow/utils/session.py", line 76, in wrapper
    return func(*args, **kwargs)
           ^^^^^^^^^^^^^^^^^^^^^
  File "/home/airflow/.local/lib/python3.12/site-packages/airflow/utils/retries.py", line 89, in wrapped_function
    for attempt in run_with_db_retries(max_retries=retries, logger=logger, **retry_kwargs):
  File "/home/airflow/.local/lib/python3.12/site-packages/tenacity/__init__.py", line 347, in __iter__
    do = self.iter(retry_state=retry_state)
         ^^^^^^^^^^^^^^^^^^^^^^^^^^^^^^^^^^
  File "/home/airflow/.local/lib/python3.12/site-packages/tenacity/__init__.py", line 325, in iter
    raise retry_exc.reraise()
          ^^^^^^^^^^^^^^^^^^^
  File "/home/airflow/.local/lib/python3.12/site-packages/tenacity/__init__.py", line 158, in reraise
    raise self.last_attempt.result()
          ^^^^^^^^^^^^^^^^^^^^^^^^^^
  File "/usr/local/lib/python3.12/concurrent/futures/_base.py", line 449, in result
    return self.__get_result()
           ^^^^^^^^^^^^^^^^^^^
  File "/usr/local/lib/python3.12/concurrent/futures/_base.py", line 401, in __get_result
    raise self._exception
  File "/home/airflow/.local/lib/python3.12/site-packages/airflow/utils/retries.py", line 98, in wrapped_function
    return func(*args, **kwargs)
           ^^^^^^^^^^^^^^^^^^^^^
  File "/home/airflow/.local/lib/python3.12/site-packages/airflow/jobs/job.py", line 316, in _fetch_from_db
    session.merge(job)
  File "/home/airflow/.local/lib/python3.12/site-packages/sqlalchemy/orm/session.py", line 3056, in merge
    return self._merge(
           ^^^^^^^^^^^^
  File "/home/airflow/.local/lib/python3.12/site-packages/sqlalchemy/orm/session.py", line 3136, in _merge
    merged = self.get(
             ^^^^^^^^^
  File "/home/airflow/.local/lib/python3.12/site-packages/sqlalchemy/orm/session.py", line 2853, in get
    return self._get_impl(
           ^^^^^^^^^^^^^^^
  File "/home/airflow/.local/lib/python3.12/site-packages/sqlalchemy/orm/session.py", line 2975, in _get_impl
    return db_load_fn(
           ^^^^^^^^^^^
  File "/home/airflow/.local/lib/python3.12/site-packages/sqlalchemy/orm/loading.py", line 530, in load_on_pk_identity
    session.execute(
  File "/home/airflow/.local/lib/python3.12/site-packages/sqlalchemy/orm/session.py", line 1716, in execute
    conn = self._connection_for_bind(bind)
           ^^^^^^^^^^^^^^^^^^^^^^^^^^^^^^^
  File "/home/airflow/.local/lib/python3.12/site-packages/sqlalchemy/orm/session.py", line 1555, in _connection_for_bind
    return self._transaction._connection_for_bind(
           ^^^^^^^^^^^^^^^^^^^^^^^^^^^^^^^^^^^^^^^
  File "/home/airflow/.local/lib/python3.12/site-packages/sqlalchemy/orm/session.py", line 750, in _connection_for_bind
    conn = bind.connect()
           ^^^^^^^^^^^^^^
  File "/home/airflow/.local/lib/python3.12/site-packages/sqlalchemy/future/engine.py", line 412, in connect
    return super(Engine, self).connect()
           ^^^^^^^^^^^^^^^^^^^^^^^^^^^^^
  File "/home/airflow/.local/lib/python3.12/site-packages/sqlalchemy/engine/base.py", line 3325, in connect
    return self._connection_cls(self, close_with_result=close_with_result)
           ^^^^^^^^^^^^^^^^^^^^^^^^^^^^^^^^^^^^^^^^^^^^^^^^^^^^^^^^^^^^^^^
  File "/home/airflow/.local/lib/python3.12/site-packages/sqlalchemy/engine/base.py", line 96, in __init__
    else engine.raw_connection()
         ^^^^^^^^^^^^^^^^^^^^^^^
  File "/home/airflow/.local/lib/python3.12/site-packages/sqlalchemy/engine/base.py", line 3404, in raw_connection
    return self._wrap_pool_connect(self.pool.connect, _connection)
           ^^^^^^^^^^^^^^^^^^^^^^^^^^^^^^^^^^^^^^^^^^^^^^^^^^^^^^^
  File "/home/airflow/.local/lib/python3.12/site-packages/sqlalchemy/engine/base.py", line 3374, in _wrap_pool_connect
    Connection._handle_dbapi_exception_noconnection(
  File "/home/airflow/.local/lib/python3.12/site-packages/sqlalchemy/engine/base.py", line 2208, in _handle_dbapi_exception_noconnection
    util.raise_(
  File "/home/airflow/.local/lib/python3.12/site-packages/sqlalchemy/util/compat.py", line 211, in raise_
    raise exception
  File "/home/airflow/.local/lib/python3.12/site-packages/sqlalchemy/engine/base.py", line 3371, in _wrap_pool_connect
    return fn()
           ^^^^
  File "/home/airflow/.local/lib/python3.12/site-packages/sqlalchemy/pool/base.py", line 327, in connect
    return _ConnectionFairy._checkout(self)
           ^^^^^^^^^^^^^^^^^^^^^^^^^^^^^^^^
  File "/home/airflow/.local/lib/python3.12/site-packages/sqlalchemy/pool/base.py", line 894, in _checkout
    fairy = _ConnectionRecord.checkout(pool)
            ^^^^^^^^^^^^^^^^^^^^^^^^^^^^^^^^
  File "/home/airflow/.local/lib/python3.12/site-packages/sqlalchemy/pool/base.py", line 493, in checkout
    rec = pool._do_get()
          ^^^^^^^^^^^^^^
  File "/home/airflow/.local/lib/python3.12/site-packages/sqlalchemy/pool/impl.py", line 256, in _do_get
    return self._create_connection()
           ^^^^^^^^^^^^^^^^^^^^^^^^^
  File "/home/airflow/.local/lib/python3.12/site-packages/sqlalchemy/pool/base.py", line 273, in _create_connection
    return _ConnectionRecord(self)
           ^^^^^^^^^^^^^^^^^^^^^^^
  File "/home/airflow/.local/lib/python3.12/site-packages/sqlalchemy/pool/base.py", line 388, in __init__
    self.__connect()
  File "/home/airflow/.local/lib/python3.12/site-packages/sqlalchemy/pool/base.py", line 690, in __connect
    with util.safe_reraise():
  File "/home/airflow/.local/lib/python3.12/site-packages/sqlalchemy/util/langhelpers.py", line 70, in __exit__
    compat.raise_(
  File "/home/airflow/.local/lib/python3.12/site-packages/sqlalchemy/util/compat.py", line 211, in raise_
    raise exception
  File "/home/airflow/.local/lib/python3.12/site-packages/sqlalchemy/pool/base.py", line 686, in __connect
    self.dbapi_connection = connection = pool._invoke_creator(self)
                                         ^^^^^^^^^^^^^^^^^^^^^^^^^^
  File "/home/airflow/.local/lib/python3.12/site-packages/sqlalchemy/engine/create.py", line 574, in connect
    return dialect.connect(*cargs, **cparams)
           ^^^^^^^^^^^^^^^^^^^^^^^^^^^^^^^^^^
  File "/home/airflow/.local/lib/python3.12/site-packages/sqlalchemy/engine/default.py", line 598, in connect
    return self.dbapi.connect(*cargs, **cparams)
           ^^^^^^^^^^^^^^^^^^^^^^^^^^^^^^^^^^^^^
  File "/home/airflow/.local/lib/python3.12/site-packages/psycopg2/__init__.py", line 122, in connect
    conn = _connect(dsn, connection_factory=connection_factory, **kwasync)
           ^^^^^^^^^^^^^^^^^^^^^^^^^^^^^^^^^^^^^^^^^^^^^^^^^^^^^^^^^^^^^^^
sqlalchemy.exc.OperationalError: (psycopg2.OperationalError) could not translate host name "postgres" to address: Temporary failure in name resolution

(Background on this error at: https://sqlalche.me/e/14/e3q8)
[2024-11-23T01:59:11.131+0000] {job.py:226} ERROR - Job heartbeat failed with error. Scheduler is in unhealthy state
[2024-11-23T01:59:16.739+0000] {logging_mixin.py:188} INFO -  1/20 ━━━━━━━━━━━━━━━━━━━━ 25:11 80s/step - loss: 0.0101
[2024-11-23T01:59:21.558+0000] {logging_mixin.py:188} INFO -  2/20 ━━━━━━━━━━━━━━━━━━━━ 24s 1s/step - loss: 0.0081   
[2024-11-23T02:00:39.747+0000] {job.py:226} ERROR - Job heartbeat failed with error. Scheduler is in unhealthy state
[2024-11-23T02:01:19.420+0000] {logging_mixin.py:188} INFO -  3/20 ━━━━━━━━━━━━━━━━━━━━ 2:14 8s/step - loss: 0.0075
[2024-11-23T02:01:19.609+0000] {logging_mixin.py:188} INFO -  4/20 ━━━━━━━━━━━━━━━━━━━━ 10:57 41s/step - loss: 0.0073
[2024-11-23T02:01:19.752+0000] {logging_mixin.py:188} INFO -  6/20 ━━━━━━━━━━━━━━━━━━━━ 5:45 25s/step - loss: 0.0072 
