[2024-11-23T01:56:45.311+0000] {local_task_job_runner.py:120} INFO - ::group::Pre task execution logs
[2024-11-23T01:56:45.750+0000] {taskinstance.py:2076} INFO - Dependencies all met for dep_context=non-requeueable deps ti=<TaskInstance: stock_price_prediction.train_model_BSP manual__2024-11-23T01:52:07.286051+00:00 [queued]>
[2024-11-23T01:56:46.027+0000] {taskinstance.py:2076} INFO - Dependencies all met for dep_context=requeueable deps ti=<TaskInstance: stock_price_prediction.train_model_BSP manual__2024-11-23T01:52:07.286051+00:00 [queued]>
[2024-11-23T01:56:46.029+0000] {taskinstance.py:2306} INFO - Starting attempt 1 of 2
[2024-11-23T01:56:46.132+0000] {taskinstance.py:2330} INFO - Executing <Task(PythonOperator): train_model_BSP> on 2024-11-23 01:52:07.286051+00:00
[2024-11-23T01:56:46.218+0000] {logging_mixin.py:188} WARNING - /home/***/.local/lib/python3.12/site-packages/***/task/task_runner/standard_task_runner.py:61 DeprecationWarning: This process (pid=5047) is multi-threaded, use of fork() may lead to deadlocks in the child.
[2024-11-23T01:56:46.223+0000] {standard_task_runner.py:63} INFO - Started process 5079 to run task
[2024-11-23T01:56:46.261+0000] {standard_task_runner.py:90} INFO - Running: ['***', 'tasks', 'run', 'stock_price_prediction', 'train_model_BSP', 'manual__2024-11-23T01:52:07.286051+00:00', '--job-id', '542', '--raw', '--subdir', 'DAGS_FOLDER/stock_price_prediction_dag.py', '--cfg-path', '/tmp/tmpfccjjueu']
[2024-11-23T01:56:46.274+0000] {standard_task_runner.py:91} INFO - Job 542: Subtask train_model_BSP
[2024-11-23T01:56:46.419+0000] {task_command.py:426} INFO - Running <TaskInstance: stock_price_prediction.train_model_BSP manual__2024-11-23T01:52:07.286051+00:00 [running]> on host ad983beda88b
[2024-11-23T01:56:46.835+0000] {taskinstance.py:2648} INFO - Exporting env vars: AIRFLOW_CTX_DAG_OWNER='***' AIRFLOW_CTX_DAG_ID='stock_price_prediction' AIRFLOW_CTX_TASK_ID='train_model_BSP' AIRFLOW_CTX_EXECUTION_DATE='2024-11-23T01:52:07.286051+00:00' AIRFLOW_CTX_TRY_NUMBER='1' AIRFLOW_CTX_DAG_RUN_ID='manual__2024-11-23T01:52:07.286051+00:00'
[2024-11-23T01:56:46.839+0000] {taskinstance.py:430} INFO - ::endgroup::
[2024-11-23T01:57:23.368+0000] {logging_mixin.py:188} WARNING - /home/***/.local/lib/python3.12/site-packages/keras/src/layers/convolutional/base_conv.py:107 UserWarning: Do not pass an `input_shape`/`input_dim` argument to a layer. When using Sequential models, prefer using an `Input(shape)` object as the first layer in the model instead.
[2024-11-23T01:57:26.565+0000] {logging_mixin.py:188} INFO - Epoch 1/20
[2024-11-23T01:57:42.028+0000] {logging_mixin.py:188} INFO -  2/37 ━━━━━━━━━━━━━━━━━━━━ 3s 104ms/step - loss: 0.1416
[2024-11-23T01:57:42.029+0000] {logging_mixin.py:188} INFO -  1/37 ━━━━━━━━━━━━━━━━━━━━ 9:12 15s/step - loss: 0.1512
[2024-11-23T01:57:42.162+0000] {logging_mixin.py:188} INFO -  3/37 ━━━━━━━━━━━━━━━━━━━━ 4s 119ms/step - loss: 0.1310
[2024-11-23T01:57:42.295+0000] {logging_mixin.py:188} INFO -  4/37 ━━━━━━━━━━━━━━━━━━━━ 4s 124ms/step - loss: 0.1218
[2024-11-23T01:57:42.486+0000] {logging_mixin.py:188} INFO -  5/37 ━━━━━━━━━━━━━━━━━━━━ 4s 140ms/step - loss: 0.1135
[2024-11-23T01:57:42.653+0000] {logging_mixin.py:188} INFO -  6/37 ━━━━━━━━━━━━━━━━━━━━ 4s 146ms/step - loss: 0.1063
[2024-11-23T01:57:42.787+0000] {logging_mixin.py:188} INFO -  7/37 ━━━━━━━━━━━━━━━━━━━━ 4s 144ms/step - loss: 0.1002
[2024-11-23T01:57:42.845+0000] {logging_mixin.py:188} INFO -  8/37 ━━━━━━━━━━━━━━━━━━━━ 3s 131ms/step - loss: 0.0951
[2024-11-23T01:57:49.332+0000] {logging_mixin.py:188} INFO -  9/37 ━━━━━━━━━━━━━━━━━━━━ 10s 378ms/step - loss: 0.0909
[2024-11-23T01:59:08.732+0000] {logging_mixin.py:188} INFO - 10/37 ━━━━━━━━━━━━━━━━━━━━ 2:35 6s/step - loss: 0.0871  
[2024-11-23T01:59:08.961+0000] {logging_mixin.py:188} INFO - 11/37 ━━━━━━━━━━━━━━━━━━━━ 3:46 9s/step - loss: 0.0836
[2024-11-23T01:59:09.015+0000] {logging_mixin.py:188} INFO - 13/37 ━━━━━━━━━━━━━━━━━━━━ 2:54 7s/step - loss: 0.0777
[2024-11-23T01:59:09.093+0000] {logging_mixin.py:188} INFO - 14/37 ━━━━━━━━━━━━━━━━━━━━ 2:34 7s/step - loss: 0.0752
[2024-11-23T01:59:09.350+0000] {logging_mixin.py:188} INFO - 15/37 ━━━━━━━━━━━━━━━━━━━━ 2:17 6s/step - loss: 0.0730
[2024-11-23T01:59:09.438+0000] {logging_mixin.py:188} INFO - 16/37 ━━━━━━━━━━━━━━━━━━━━ 2:02 6s/step - loss: 0.0710
[2024-11-23T01:59:09.919+0000] {logging_mixin.py:188} INFO - 17/37 ━━━━━━━━━━━━━━━━━━━━ 1:49 5s/step - loss: 0.0691
[2024-11-23T01:59:10.025+0000] {logging_mixin.py:188} INFO - 18/37 ━━━━━━━━━━━━━━━━━━━━ 1:38 5s/step - loss: 0.0673
[2024-11-23T01:59:10.245+0000] {logging_mixin.py:188} INFO - 19/37 ━━━━━━━━━━━━━━━━━━━━ 1:28 5s/step - loss: 0.0657
[2024-11-23T01:59:10.645+0000] {logging_mixin.py:188} INFO - 20/37 ━━━━━━━━━━━━━━━━━━━━ 1:19 5s/step - loss: 0.0641
[2024-11-23T01:59:10.738+0000] {logging_mixin.py:188} INFO - 21/37 ━━━━━━━━━━━━━━━━━━━━ 1:11 4s/step - loss: 0.0627
[2024-11-23T01:59:10.801+0000] {logging_mixin.py:188} INFO - 24/37 ━━━━━━━━━━━━━━━━━━━━ 50s 4s/step - loss: 0.0588 
[2024-11-23T01:59:10.877+0000] {logging_mixin.py:188} INFO - 26/37 ━━━━━━━━━━━━━━━━━━━━ 39s 4s/step - loss: 0.0565
[2024-11-23T01:59:10.946+0000] {logging_mixin.py:188} INFO - 28/37 ━━━━━━━━━━━━━━━━━━━━ 29s 3s/step - loss: 0.0545
[2024-11-23T01:59:11.008+0000] {logging_mixin.py:188} INFO - 29/37 ━━━━━━━━━━━━━━━━━━━━ 25s 3s/step - loss: 0.0535
[2024-11-23T01:59:11.116+0000] {logging_mixin.py:188} INFO - 31/37 ━━━━━━━━━━━━━━━━━━━━ 17s 3s/step - loss: 0.0518
[2024-11-23T01:59:11.173+0000] {logging_mixin.py:188} INFO - 33/37 ━━━━━━━━━━━━━━━━━━━━ 11s 3s/step - loss: 0.0501
[2024-11-23T01:58:47.292+0000] {job.py:218} ERROR - Job heartbeat got an exception
Traceback (most recent call last):
  File "/home/airflow/.local/lib/python3.12/site-packages/sqlalchemy/engine/base.py", line 3371, in _wrap_pool_connect
    return fn()
           ^^^^
  File "/home/airflow/.local/lib/python3.12/site-packages/sqlalchemy/pool/base.py", line 327, in connect
    return _ConnectionFairy._checkout(self)
           ^^^^^^^^^^^^^^^^^^^^^^^^^^^^^^^^
  File "/home/airflow/.local/lib/python3.12/site-packages/sqlalchemy/pool/base.py", line 894, in _checkout
    fairy = _ConnectionRecord.checkout(pool)
            ^^^^^^^^^^^^^^^^^^^^^^^^^^^^^^^^
  File "/home/airflow/.local/lib/python3.12/site-packages/sqlalchemy/pool/base.py", line 493, in checkout
    rec = pool._do_get()
          ^^^^^^^^^^^^^^
  File "/home/airflow/.local/lib/python3.12/site-packages/sqlalchemy/pool/impl.py", line 256, in _do_get
    return self._create_connection()
           ^^^^^^^^^^^^^^^^^^^^^^^^^
  File "/home/airflow/.local/lib/python3.12/site-packages/sqlalchemy/pool/base.py", line 273, in _create_connection
    return _ConnectionRecord(self)
           ^^^^^^^^^^^^^^^^^^^^^^^
  File "/home/airflow/.local/lib/python3.12/site-packages/sqlalchemy/pool/base.py", line 388, in __init__
    self.__connect()
  File "/home/airflow/.local/lib/python3.12/site-packages/sqlalchemy/pool/base.py", line 690, in __connect
    with util.safe_reraise():
  File "/home/airflow/.local/lib/python3.12/site-packages/sqlalchemy/util/langhelpers.py", line 70, in __exit__
    compat.raise_(
  File "/home/airflow/.local/lib/python3.12/site-packages/sqlalchemy/util/compat.py", line 211, in raise_
    raise exception
  File "/home/airflow/.local/lib/python3.12/site-packages/sqlalchemy/pool/base.py", line 686, in __connect
    self.dbapi_connection = connection = pool._invoke_creator(self)
                                         ^^^^^^^^^^^^^^^^^^^^^^^^^^
  File "/home/airflow/.local/lib/python3.12/site-packages/sqlalchemy/engine/create.py", line 574, in connect
    return dialect.connect(*cargs, **cparams)
           ^^^^^^^^^^^^^^^^^^^^^^^^^^^^^^^^^^
  File "/home/airflow/.local/lib/python3.12/site-packages/sqlalchemy/engine/default.py", line 598, in connect
    return self.dbapi.connect(*cargs, **cparams)
           ^^^^^^^^^^^^^^^^^^^^^^^^^^^^^^^^^^^^^
  File "/home/airflow/.local/lib/python3.12/site-packages/psycopg2/__init__.py", line 122, in connect
    conn = _connect(dsn, connection_factory=connection_factory, **kwasync)
           ^^^^^^^^^^^^^^^^^^^^^^^^^^^^^^^^^^^^^^^^^^^^^^^^^^^^^^^^^^^^^^^
psycopg2.OperationalError: could not translate host name "postgres" to address: Temporary failure in name resolution


The above exception was the direct cause of the following exception:

Traceback (most recent call last):
  File "/home/airflow/.local/lib/python3.12/site-packages/airflow/jobs/job.py", line 192, in heartbeat
    self._merge_from(Job._fetch_from_db(self, session))
                     ^^^^^^^^^^^^^^^^^^^^^^^^^^^^^^^^^
  File "/home/airflow/.local/lib/python3.12/site-packages/airflow/api_internal/internal_api_call.py", line 115, in wrapper
    return func(*args, **kwargs)
           ^^^^^^^^^^^^^^^^^^^^^
  File "/home/airflow/.local/lib/python3.12/site-packages/airflow/utils/session.py", line 76, in wrapper
    return func(*args, **kwargs)
           ^^^^^^^^^^^^^^^^^^^^^
  File "/home/airflow/.local/lib/python3.12/site-packages/airflow/utils/retries.py", line 89, in wrapped_function
    for attempt in run_with_db_retries(max_retries=retries, logger=logger, **retry_kwargs):
  File "/home/airflow/.local/lib/python3.12/site-packages/tenacity/__init__.py", line 347, in __iter__
    do = self.iter(retry_state=retry_state)
         ^^^^^^^^^^^^^^^^^^^^^^^^^^^^^^^^^^
  File "/home/airflow/.local/lib/python3.12/site-packages/tenacity/__init__.py", line 325, in iter
    raise retry_exc.reraise()
          ^^^^^^^^^^^^^^^^^^^
  File "/home/airflow/.local/lib/python3.12/site-packages/tenacity/__init__.py", line 158, in reraise
    raise self.last_attempt.result()
          ^^^^^^^^^^^^^^^^^^^^^^^^^^
  File "/usr/local/lib/python3.12/concurrent/futures/_base.py", line 449, in result
    return self.__get_result()
           ^^^^^^^^^^^^^^^^^^^
  File "/usr/local/lib/python3.12/concurrent/futures/_base.py", line 401, in __get_result
    raise self._exception
  File "/home/airflow/.local/lib/python3.12/site-packages/airflow/utils/retries.py", line 98, in wrapped_function
    return func(*args, **kwargs)
           ^^^^^^^^^^^^^^^^^^^^^
  File "/home/airflow/.local/lib/python3.12/site-packages/airflow/jobs/job.py", line 316, in _fetch_from_db
    session.merge(job)
  File "/home/airflow/.local/lib/python3.12/site-packages/sqlalchemy/orm/session.py", line 3056, in merge
    return self._merge(
           ^^^^^^^^^^^^
  File "/home/airflow/.local/lib/python3.12/site-packages/sqlalchemy/orm/session.py", line 3136, in _merge
    merged = self.get(
             ^^^^^^^^^
  File "/home/airflow/.local/lib/python3.12/site-packages/sqlalchemy/orm/session.py", line 2853, in get
    return self._get_impl(
           ^^^^^^^^^^^^^^^
  File "/home/airflow/.local/lib/python3.12/site-packages/sqlalchemy/orm/session.py", line 2975, in _get_impl
    return db_load_fn(
           ^^^^^^^^^^^
  File "/home/airflow/.local/lib/python3.12/site-packages/sqlalchemy/orm/loading.py", line 530, in load_on_pk_identity
    session.execute(
  File "/home/airflow/.local/lib/python3.12/site-packages/sqlalchemy/orm/session.py", line 1716, in execute
    conn = self._connection_for_bind(bind)
           ^^^^^^^^^^^^^^^^^^^^^^^^^^^^^^^
  File "/home/airflow/.local/lib/python3.12/site-packages/sqlalchemy/orm/session.py", line 1555, in _connection_for_bind
    return self._transaction._connection_for_bind(
           ^^^^^^^^^^^^^^^^^^^^^^^^^^^^^^^^^^^^^^^
  File "/home/airflow/.local/lib/python3.12/site-packages/sqlalchemy/orm/session.py", line 750, in _connection_for_bind
    conn = bind.connect()
           ^^^^^^^^^^^^^^
  File "/home/airflow/.local/lib/python3.12/site-packages/sqlalchemy/future/engine.py", line 412, in connect
    return super(Engine, self).connect()
           ^^^^^^^^^^^^^^^^^^^^^^^^^^^^^
  File "/home/airflow/.local/lib/python3.12/site-packages/sqlalchemy/engine/base.py", line 3325, in connect
    return self._connection_cls(self, close_with_result=close_with_result)
           ^^^^^^^^^^^^^^^^^^^^^^^^^^^^^^^^^^^^^^^^^^^^^^^^^^^^^^^^^^^^^^^
  File "/home/airflow/.local/lib/python3.12/site-packages/sqlalchemy/engine/base.py", line 96, in __init__
    else engine.raw_connection()
         ^^^^^^^^^^^^^^^^^^^^^^^
  File "/home/airflow/.local/lib/python3.12/site-packages/sqlalchemy/engine/base.py", line 3404, in raw_connection
    return self._wrap_pool_connect(self.pool.connect, _connection)
           ^^^^^^^^^^^^^^^^^^^^^^^^^^^^^^^^^^^^^^^^^^^^^^^^^^^^^^^
  File "/home/airflow/.local/lib/python3.12/site-packages/sqlalchemy/engine/base.py", line 3374, in _wrap_pool_connect
    Connection._handle_dbapi_exception_noconnection(
  File "/home/airflow/.local/lib/python3.12/site-packages/sqlalchemy/engine/base.py", line 2208, in _handle_dbapi_exception_noconnection
    util.raise_(
  File "/home/airflow/.local/lib/python3.12/site-packages/sqlalchemy/util/compat.py", line 211, in raise_
    raise exception
  File "/home/airflow/.local/lib/python3.12/site-packages/sqlalchemy/engine/base.py", line 3371, in _wrap_pool_connect
    return fn()
           ^^^^
  File "/home/airflow/.local/lib/python3.12/site-packages/sqlalchemy/pool/base.py", line 327, in connect
    return _ConnectionFairy._checkout(self)
           ^^^^^^^^^^^^^^^^^^^^^^^^^^^^^^^^
  File "/home/airflow/.local/lib/python3.12/site-packages/sqlalchemy/pool/base.py", line 894, in _checkout
    fairy = _ConnectionRecord.checkout(pool)
            ^^^^^^^^^^^^^^^^^^^^^^^^^^^^^^^^
  File "/home/airflow/.local/lib/python3.12/site-packages/sqlalchemy/pool/base.py", line 493, in checkout
    rec = pool._do_get()
          ^^^^^^^^^^^^^^
  File "/home/airflow/.local/lib/python3.12/site-packages/sqlalchemy/pool/impl.py", line 256, in _do_get
    return self._create_connection()
           ^^^^^^^^^^^^^^^^^^^^^^^^^
  File "/home/airflow/.local/lib/python3.12/site-packages/sqlalchemy/pool/base.py", line 273, in _create_connection
    return _ConnectionRecord(self)
           ^^^^^^^^^^^^^^^^^^^^^^^
  File "/home/airflow/.local/lib/python3.12/site-packages/sqlalchemy/pool/base.py", line 388, in __init__
    self.__connect()
  File "/home/airflow/.local/lib/python3.12/site-packages/sqlalchemy/pool/base.py", line 690, in __connect
    with util.safe_reraise():
  File "/home/airflow/.local/lib/python3.12/site-packages/sqlalchemy/util/langhelpers.py", line 70, in __exit__
    compat.raise_(
  File "/home/airflow/.local/lib/python3.12/site-packages/sqlalchemy/util/compat.py", line 211, in raise_
    raise exception
  File "/home/airflow/.local/lib/python3.12/site-packages/sqlalchemy/pool/base.py", line 686, in __connect
    self.dbapi_connection = connection = pool._invoke_creator(self)
                                         ^^^^^^^^^^^^^^^^^^^^^^^^^^
  File "/home/airflow/.local/lib/python3.12/site-packages/sqlalchemy/engine/create.py", line 574, in connect
    return dialect.connect(*cargs, **cparams)
           ^^^^^^^^^^^^^^^^^^^^^^^^^^^^^^^^^^
  File "/home/airflow/.local/lib/python3.12/site-packages/sqlalchemy/engine/default.py", line 598, in connect
    return self.dbapi.connect(*cargs, **cparams)
           ^^^^^^^^^^^^^^^^^^^^^^^^^^^^^^^^^^^^^
  File "/home/airflow/.local/lib/python3.12/site-packages/psycopg2/__init__.py", line 122, in connect
    conn = _connect(dsn, connection_factory=connection_factory, **kwasync)
           ^^^^^^^^^^^^^^^^^^^^^^^^^^^^^^^^^^^^^^^^^^^^^^^^^^^^^^^^^^^^^^^
sqlalchemy.exc.OperationalError: (psycopg2.OperationalError) could not translate host name "postgres" to address: Temporary failure in name resolution

(Background on this error at: https://sqlalche.me/e/14/e3q8)
[2024-11-23T01:59:11.338+0000] {job.py:226} ERROR - Job heartbeat failed with error. Scheduler is in unhealthy state
[2024-11-23T01:59:11.740+0000] {logging_mixin.py:188} INFO - 34/37 ━━━━━━━━━━━━━━━━━━━━ 8s 3s/step - loss: 0.0494 
[2024-11-23T01:59:12.676+0000] {logging_mixin.py:188} INFO - 35/37 ━━━━━━━━━━━━━━━━━━━━ 5s 3s/step - loss: 0.0486
[2024-11-23T01:59:12.749+0000] {logging_mixin.py:188} INFO - 36/37 ━━━━━━━━━━━━━━━━━━━━ 2s 3s/step - loss: 0.0479
[2024-11-23T01:59:16.444+0000] {logging_mixin.py:188} INFO - 37/37 ━━━━━━━━━━━━━━━━━━━━ 109s 3s/step - loss: 0.0466
[2024-11-23T01:59:16.854+0000] {logging_mixin.py:188} INFO - Epoch 2/20
[2024-11-23T02:00:45.346+0000] {job.py:226} ERROR - Job heartbeat failed with error. Scheduler is in unhealthy state
[2024-11-23T02:01:19.699+0000] {logging_mixin.py:188} INFO -  1/37 ━━━━━━━━━━━━━━━━━━━━ 1:13:43 123s/step - loss: 0.0101
[2024-11-23T02:01:19.727+0000] {logging_mixin.py:188} INFO -  2/37 ━━━━━━━━━━━━━━━━━━━━ 1s 34ms/step - loss: 0.0090
