[2024-11-23T01:56:45.216+0000] {local_task_job_runner.py:120} INFO - ::group::Pre task execution logs
[2024-11-23T01:56:45.681+0000] {taskinstance.py:2076} INFO - Dependencies all met for dep_context=non-requeueable deps ti=<TaskInstance: stock_price_prediction.train_model_BLT manual__2024-11-23T01:52:07.286051+00:00 [queued]>
[2024-11-23T01:56:45.921+0000] {taskinstance.py:2076} INFO - Dependencies all met for dep_context=requeueable deps ti=<TaskInstance: stock_price_prediction.train_model_BLT manual__2024-11-23T01:52:07.286051+00:00 [queued]>
[2024-11-23T01:56:45.922+0000] {taskinstance.py:2306} INFO - Starting attempt 1 of 2
[2024-11-23T01:56:45.965+0000] {taskinstance.py:2330} INFO - Executing <Task(PythonOperator): train_model_BLT> on 2024-11-23 01:52:07.286051+00:00
[2024-11-23T01:56:45.988+0000] {logging_mixin.py:188} WARNING - /home/***/.local/lib/python3.12/site-packages/***/task/task_runner/standard_task_runner.py:61 DeprecationWarning: This process (pid=5050) is multi-threaded, use of fork() may lead to deadlocks in the child.
[2024-11-23T01:56:45.990+0000] {standard_task_runner.py:63} INFO - Started process 5056 to run task
[2024-11-23T01:56:46.006+0000] {standard_task_runner.py:90} INFO - Running: ['***', 'tasks', 'run', 'stock_price_prediction', 'train_model_BLT', 'manual__2024-11-23T01:52:07.286051+00:00', '--job-id', '541', '--raw', '--subdir', 'DAGS_FOLDER/stock_price_prediction_dag.py', '--cfg-path', '/tmp/tmpywxq726m']
[2024-11-23T01:56:46.026+0000] {standard_task_runner.py:91} INFO - Job 541: Subtask train_model_BLT
[2024-11-23T01:56:46.257+0000] {task_command.py:426} INFO - Running <TaskInstance: stock_price_prediction.train_model_BLT manual__2024-11-23T01:52:07.286051+00:00 [running]> on host ad983beda88b
[2024-11-23T01:56:46.554+0000] {taskinstance.py:2648} INFO - Exporting env vars: AIRFLOW_CTX_DAG_OWNER='***' AIRFLOW_CTX_DAG_ID='stock_price_prediction' AIRFLOW_CTX_TASK_ID='train_model_BLT' AIRFLOW_CTX_EXECUTION_DATE='2024-11-23T01:52:07.286051+00:00' AIRFLOW_CTX_TRY_NUMBER='1' AIRFLOW_CTX_DAG_RUN_ID='manual__2024-11-23T01:52:07.286051+00:00'
[2024-11-23T01:56:46.561+0000] {taskinstance.py:430} INFO - ::endgroup::
[2024-11-23T01:57:23.369+0000] {logging_mixin.py:188} WARNING - /home/***/.local/lib/python3.12/site-packages/keras/src/layers/convolutional/base_conv.py:107 UserWarning: Do not pass an `input_shape`/`input_dim` argument to a layer. When using Sequential models, prefer using an `Input(shape)` object as the first layer in the model instead.
[2024-11-23T01:57:26.200+0000] {logging_mixin.py:188} INFO - Epoch 1/20
[2024-11-23T01:57:42.182+0000] {logging_mixin.py:188} INFO -  1/39 ━━━━━━━━━━━━━━━━━━━━ 9:54 16s/step - loss: 0.0865
[2024-11-23T01:57:42.221+0000] {logging_mixin.py:188} INFO -  2/39 ━━━━━━━━━━━━━━━━━━━━ 12s 326ms/step - loss: 0.0817
[2024-11-23T01:57:42.707+0000] {logging_mixin.py:188} INFO -  3/39 ━━━━━━━━━━━━━━━━━━━━ 15s 430ms/step - loss: 0.0751
[2024-11-23T01:57:42.885+0000] {logging_mixin.py:188} INFO -  4/39 ━━━━━━━━━━━━━━━━━━━━ 12s 346ms/step - loss: 0.0688
[2024-11-23T01:57:45.908+0000] {logging_mixin.py:188} INFO -  5/39 ━━━━━━━━━━━━━━━━━━━━ 16s 500ms/step - loss: 0.0634
[2024-11-23T01:58:40.788+0000] {logging_mixin.py:188} INFO -  6/39 ━━━━━━━━━━━━━━━━━━━━ 50s 2s/step - loss: 0.0592   
[2024-11-23T01:59:08.767+0000] {logging_mixin.py:188} INFO -  7/39 ━━━━━━━━━━━━━━━━━━━━ 7:43 14s/step - loss: 0.0561
[2024-11-23T01:59:09.043+0000] {logging_mixin.py:188} INFO -  8/39 ━━━━━━━━━━━━━━━━━━━━ 6:26 12s/step - loss: 0.0535
[2024-11-23T01:59:09.691+0000] {logging_mixin.py:188} INFO -  9/39 ━━━━━━━━━━━━━━━━━━━━ 5:29 11s/step - loss: 0.0511
[2024-11-23T01:59:10.101+0000] {logging_mixin.py:188} INFO - 10/39 ━━━━━━━━━━━━━━━━━━━━ 4:44 10s/step - loss: 0.0489
[2024-11-23T01:59:10.194+0000] {logging_mixin.py:188} INFO - 11/39 ━━━━━━━━━━━━━━━━━━━━ 4:07 9s/step - loss: 0.0471 
[2024-11-23T01:59:10.280+0000] {logging_mixin.py:188} INFO - 12/39 ━━━━━━━━━━━━━━━━━━━━ 3:37 8s/step - loss: 0.0454
[2024-11-23T01:59:10.336+0000] {logging_mixin.py:188} INFO - 13/39 ━━━━━━━━━━━━━━━━━━━━ 3:11 7s/step - loss: 0.0438
[2024-11-23T01:59:10.416+0000] {logging_mixin.py:188} INFO - 15/39 ━━━━━━━━━━━━━━━━━━━━ 2:31 6s/step - loss: 0.0413
[2024-11-23T01:59:10.540+0000] {logging_mixin.py:188} INFO - 17/39 ━━━━━━━━━━━━━━━━━━━━ 2:01 6s/step - loss: 0.0390
[2024-11-23T01:59:10.612+0000] {logging_mixin.py:188} INFO - 18/39 ━━━━━━━━━━━━━━━━━━━━ 1:49 5s/step - loss: 0.0380
[2024-11-23T01:59:10.693+0000] {logging_mixin.py:188} INFO - 20/39 ━━━━━━━━━━━━━━━━━━━━ 1:28 5s/step - loss: 0.0361
[2024-11-23T01:59:10.751+0000] {logging_mixin.py:188} INFO - 21/39 ━━━━━━━━━━━━━━━━━━━━ 1:20 4s/step - loss: 0.0353
[2024-11-23T01:59:10.822+0000] {logging_mixin.py:188} INFO - 23/39 ━━━━━━━━━━━━━━━━━━━━ 1:04 4s/step - loss: 0.0337
[2024-11-23T01:59:10.896+0000] {logging_mixin.py:188} INFO - 24/39 ━━━━━━━━━━━━━━━━━━━━ 58s 4s/step - loss: 0.0330 
[2024-11-23T01:59:10.948+0000] {logging_mixin.py:188} INFO - 25/39 ━━━━━━━━━━━━━━━━━━━━ 51s 4s/step - loss: 0.0324
[2024-11-23T01:59:11.008+0000] {logging_mixin.py:188} INFO - 26/39 ━━━━━━━━━━━━━━━━━━━━ 46s 4s/step - loss: 0.0317
[2024-11-23T01:58:51.693+0000] {job.py:218} ERROR - Job heartbeat got an exception
Traceback (most recent call last):
  File "/home/airflow/.local/lib/python3.12/site-packages/sqlalchemy/engine/base.py", line 3371, in _wrap_pool_connect
    return fn()
           ^^^^
  File "/home/airflow/.local/lib/python3.12/site-packages/sqlalchemy/pool/base.py", line 327, in connect
    return _ConnectionFairy._checkout(self)
           ^^^^^^^^^^^^^^^^^^^^^^^^^^^^^^^^
  File "/home/airflow/.local/lib/python3.12/site-packages/sqlalchemy/pool/base.py", line 894, in _checkout
    fairy = _ConnectionRecord.checkout(pool)
            ^^^^^^^^^^^^^^^^^^^^^^^^^^^^^^^^
  File "/home/airflow/.local/lib/python3.12/site-packages/sqlalchemy/pool/base.py", line 493, in checkout
    rec = pool._do_get()
          ^^^^^^^^^^^^^^
  File "/home/airflow/.local/lib/python3.12/site-packages/sqlalchemy/pool/impl.py", line 256, in _do_get
    return self._create_connection()
           ^^^^^^^^^^^^^^^^^^^^^^^^^
  File "/home/airflow/.local/lib/python3.12/site-packages/sqlalchemy/pool/base.py", line 273, in _create_connection
    return _ConnectionRecord(self)
           ^^^^^^^^^^^^^^^^^^^^^^^
  File "/home/airflow/.local/lib/python3.12/site-packages/sqlalchemy/pool/base.py", line 388, in __init__
    self.__connect()
  File "/home/airflow/.local/lib/python3.12/site-packages/sqlalchemy/pool/base.py", line 690, in __connect
    with util.safe_reraise():
  File "/home/airflow/.local/lib/python3.12/site-packages/sqlalchemy/util/langhelpers.py", line 70, in __exit__
    compat.raise_(
  File "/home/airflow/.local/lib/python3.12/site-packages/sqlalchemy/util/compat.py", line 211, in raise_
    raise exception
  File "/home/airflow/.local/lib/python3.12/site-packages/sqlalchemy/pool/base.py", line 686, in __connect
    self.dbapi_connection = connection = pool._invoke_creator(self)
                                         ^^^^^^^^^^^^^^^^^^^^^^^^^^
  File "/home/airflow/.local/lib/python3.12/site-packages/sqlalchemy/engine/create.py", line 574, in connect
    return dialect.connect(*cargs, **cparams)
           ^^^^^^^^^^^^^^^^^^^^^^^^^^^^^^^^^^
  File "/home/airflow/.local/lib/python3.12/site-packages/sqlalchemy/engine/default.py", line 598, in connect
    return self.dbapi.connect(*cargs, **cparams)
           ^^^^^^^^^^^^^^^^^^^^^^^^^^^^^^^^^^^^^
  File "/home/airflow/.local/lib/python3.12/site-packages/psycopg2/__init__.py", line 122, in connect
    conn = _connect(dsn, connection_factory=connection_factory, **kwasync)
           ^^^^^^^^^^^^^^^^^^^^^^^^^^^^^^^^^^^^^^^^^^^^^^^^^^^^^^^^^^^^^^^
psycopg2.OperationalError: could not translate host name "postgres" to address: Temporary failure in name resolution


The above exception was the direct cause of the following exception:

Traceback (most recent call last):
  File "/home/airflow/.local/lib/python3.12/site-packages/airflow/jobs/job.py", line 192, in heartbeat
    self._merge_from(Job._fetch_from_db(self, session))
                     ^^^^^^^^^^^^^^^^^^^^^^^^^^^^^^^^^
  File "/home/airflow/.local/lib/python3.12/site-packages/airflow/api_internal/internal_api_call.py", line 115, in wrapper
    return func(*args, **kwargs)
           ^^^^^^^^^^^^^^^^^^^^^
  File "/home/airflow/.local/lib/python3.12/site-packages/airflow/utils/session.py", line 76, in wrapper
    return func(*args, **kwargs)
           ^^^^^^^^^^^^^^^^^^^^^
  File "/home/airflow/.local/lib/python3.12/site-packages/airflow/utils/retries.py", line 89, in wrapped_function
    for attempt in run_with_db_retries(max_retries=retries, logger=logger, **retry_kwargs):
  File "/home/airflow/.local/lib/python3.12/site-packages/tenacity/__init__.py", line 347, in __iter__
    do = self.iter(retry_state=retry_state)
         ^^^^^^^^^^^^^^^^^^^^^^^^^^^^^^^^^^
  File "/home/airflow/.local/lib/python3.12/site-packages/tenacity/__init__.py", line 325, in iter
    raise retry_exc.reraise()
          ^^^^^^^^^^^^^^^^^^^
  File "/home/airflow/.local/lib/python3.12/site-packages/tenacity/__init__.py", line 158, in reraise
    raise self.last_attempt.result()
          ^^^^^^^^^^^^^^^^^^^^^^^^^^
  File "/usr/local/lib/python3.12/concurrent/futures/_base.py", line 449, in result
    return self.__get_result()
           ^^^^^^^^^^^^^^^^^^^
  File "/usr/local/lib/python3.12/concurrent/futures/_base.py", line 401, in __get_result
    raise self._exception
  File "/home/airflow/.local/lib/python3.12/site-packages/airflow/utils/retries.py", line 98, in wrapped_function
    return func(*args, **kwargs)
           ^^^^^^^^^^^^^^^^^^^^^
  File "/home/airflow/.local/lib/python3.12/site-packages/airflow/jobs/job.py", line 316, in _fetch_from_db
    session.merge(job)
  File "/home/airflow/.local/lib/python3.12/site-packages/sqlalchemy/orm/session.py", line 3056, in merge
    return self._merge(
           ^^^^^^^^^^^^
  File "/home/airflow/.local/lib/python3.12/site-packages/sqlalchemy/orm/session.py", line 3136, in _merge
    merged = self.get(
             ^^^^^^^^^
  File "/home/airflow/.local/lib/python3.12/site-packages/sqlalchemy/orm/session.py", line 2853, in get
    return self._get_impl(
           ^^^^^^^^^^^^^^^
  File "/home/airflow/.local/lib/python3.12/site-packages/sqlalchemy/orm/session.py", line 2975, in _get_impl
    return db_load_fn(
           ^^^^^^^^^^^
  File "/home/airflow/.local/lib/python3.12/site-packages/sqlalchemy/orm/loading.py", line 530, in load_on_pk_identity
    session.execute(
  File "/home/airflow/.local/lib/python3.12/site-packages/sqlalchemy/orm/session.py", line 1716, in execute
    conn = self._connection_for_bind(bind)
           ^^^^^^^^^^^^^^^^^^^^^^^^^^^^^^^
  File "/home/airflow/.local/lib/python3.12/site-packages/sqlalchemy/orm/session.py", line 1555, in _connection_for_bind
    return self._transaction._connection_for_bind(
           ^^^^^^^^^^^^^^^^^^^^^^^^^^^^^^^^^^^^^^^
  File "/home/airflow/.local/lib/python3.12/site-packages/sqlalchemy/orm/session.py", line 750, in _connection_for_bind
    conn = bind.connect()
           ^^^^^^^^^^^^^^
  File "/home/airflow/.local/lib/python3.12/site-packages/sqlalchemy/future/engine.py", line 412, in connect
    return super(Engine, self).connect()
           ^^^^^^^^^^^^^^^^^^^^^^^^^^^^^
  File "/home/airflow/.local/lib/python3.12/site-packages/sqlalchemy/engine/base.py", line 3325, in connect
    return self._connection_cls(self, close_with_result=close_with_result)
           ^^^^^^^^^^^^^^^^^^^^^^^^^^^^^^^^^^^^^^^^^^^^^^^^^^^^^^^^^^^^^^^
  File "/home/airflow/.local/lib/python3.12/site-packages/sqlalchemy/engine/base.py", line 96, in __init__
    else engine.raw_connection()
         ^^^^^^^^^^^^^^^^^^^^^^^
  File "/home/airflow/.local/lib/python3.12/site-packages/sqlalchemy/engine/base.py", line 3404, in raw_connection
    return self._wrap_pool_connect(self.pool.connect, _connection)
           ^^^^^^^^^^^^^^^^^^^^^^^^^^^^^^^^^^^^^^^^^^^^^^^^^^^^^^^
  File "/home/airflow/.local/lib/python3.12/site-packages/sqlalchemy/engine/base.py", line 3374, in _wrap_pool_connect
    Connection._handle_dbapi_exception_noconnection(
  File "/home/airflow/.local/lib/python3.12/site-packages/sqlalchemy/engine/base.py", line 2208, in _handle_dbapi_exception_noconnection
    util.raise_(
  File "/home/airflow/.local/lib/python3.12/site-packages/sqlalchemy/util/compat.py", line 211, in raise_
    raise exception
  File "/home/airflow/.local/lib/python3.12/site-packages/sqlalchemy/engine/base.py", line 3371, in _wrap_pool_connect
    return fn()
           ^^^^
  File "/home/airflow/.local/lib/python3.12/site-packages/sqlalchemy/pool/base.py", line 327, in connect
    return _ConnectionFairy._checkout(self)
           ^^^^^^^^^^^^^^^^^^^^^^^^^^^^^^^^
  File "/home/airflow/.local/lib/python3.12/site-packages/sqlalchemy/pool/base.py", line 894, in _checkout
    fairy = _ConnectionRecord.checkout(pool)
            ^^^^^^^^^^^^^^^^^^^^^^^^^^^^^^^^
  File "/home/airflow/.local/lib/python3.12/site-packages/sqlalchemy/pool/base.py", line 493, in checkout
    rec = pool._do_get()
          ^^^^^^^^^^^^^^
  File "/home/airflow/.local/lib/python3.12/site-packages/sqlalchemy/pool/impl.py", line 256, in _do_get
    return self._create_connection()
           ^^^^^^^^^^^^^^^^^^^^^^^^^
  File "/home/airflow/.local/lib/python3.12/site-packages/sqlalchemy/pool/base.py", line 273, in _create_connection
    return _ConnectionRecord(self)
           ^^^^^^^^^^^^^^^^^^^^^^^
  File "/home/airflow/.local/lib/python3.12/site-packages/sqlalchemy/pool/base.py", line 388, in __init__
    self.__connect()
  File "/home/airflow/.local/lib/python3.12/site-packages/sqlalchemy/pool/base.py", line 690, in __connect
    with util.safe_reraise():
  File "/home/airflow/.local/lib/python3.12/site-packages/sqlalchemy/util/langhelpers.py", line 70, in __exit__
    compat.raise_(
  File "/home/airflow/.local/lib/python3.12/site-packages/sqlalchemy/util/compat.py", line 211, in raise_
    raise exception
  File "/home/airflow/.local/lib/python3.12/site-packages/sqlalchemy/pool/base.py", line 686, in __connect
    self.dbapi_connection = connection = pool._invoke_creator(self)
                                         ^^^^^^^^^^^^^^^^^^^^^^^^^^
  File "/home/airflow/.local/lib/python3.12/site-packages/sqlalchemy/engine/create.py", line 574, in connect
    return dialect.connect(*cargs, **cparams)
           ^^^^^^^^^^^^^^^^^^^^^^^^^^^^^^^^^^
  File "/home/airflow/.local/lib/python3.12/site-packages/sqlalchemy/engine/default.py", line 598, in connect
    return self.dbapi.connect(*cargs, **cparams)
           ^^^^^^^^^^^^^^^^^^^^^^^^^^^^^^^^^^^^^
  File "/home/airflow/.local/lib/python3.12/site-packages/psycopg2/__init__.py", line 122, in connect
    conn = _connect(dsn, connection_factory=connection_factory, **kwasync)
           ^^^^^^^^^^^^^^^^^^^^^^^^^^^^^^^^^^^^^^^^^^^^^^^^^^^^^^^^^^^^^^^
sqlalchemy.exc.OperationalError: (psycopg2.OperationalError) could not translate host name "postgres" to address: Temporary failure in name resolution

(Background on this error at: https://sqlalche.me/e/14/e3q8)
[2024-11-23T01:59:11.066+0000] {job.py:226} ERROR - Job heartbeat failed with error. Scheduler is in unhealthy state
[2024-11-23T01:59:11.095+0000] {logging_mixin.py:188} INFO - 28/39 ━━━━━━━━━━━━━━━━━━━━ 36s 3s/step - loss: 0.0306
[2024-11-23T01:59:11.173+0000] {logging_mixin.py:188} INFO - 30/39 ━━━━━━━━━━━━━━━━━━━━ 27s 3s/step - loss: 0.0295
[2024-11-23T01:59:11.234+0000] {logging_mixin.py:188} INFO - 31/39 ━━━━━━━━━━━━━━━━━━━━ 23s 3s/step - loss: 0.0290
[2024-11-23T01:59:11.304+0000] {logging_mixin.py:188} INFO - 33/39 ━━━━━━━━━━━━━━━━━━━━ 16s 3s/step - loss: 0.0280
[2024-11-23T01:59:11.740+0000] {logging_mixin.py:188} INFO - 36/39 ━━━━━━━━━━━━━━━━━━━━ 7s 3s/step - loss: 0.0268 
[2024-11-23T01:59:12.676+0000] {logging_mixin.py:188} INFO - 37/39 ━━━━━━━━━━━━━━━━━━━━ 5s 3s/step - loss: 0.0264
[2024-11-23T01:59:12.708+0000] {logging_mixin.py:188} INFO - 38/39 ━━━━━━━━━━━━━━━━━━━━ 2s 2s/step - loss: 0.0260
[2024-11-23T01:59:16.184+0000] {logging_mixin.py:188} INFO - 39/39 ━━━━━━━━━━━━━━━━━━━━ 109s 2s/step - loss: 0.0253
[2024-11-23T01:59:16.470+0000] {logging_mixin.py:188} INFO - Epoch 2/20
[2024-11-23T02:00:46.516+0000] {job.py:226} ERROR - Job heartbeat failed with error. Scheduler is in unhealthy state
[2024-11-23T02:01:19.642+0000] {logging_mixin.py:188} INFO -  1/39 ━━━━━━━━━━━━━━━━━━━━ 1:18:02 123s/step - loss: 0.0045
[2024-11-23T02:01:19.778+0000] {logging_mixin.py:188} INFO -  2/39 ━━━━━━━━━━━━━━━━━━━━ 5s 136ms/step - loss: 0.0043    
