[2024-11-23T01:56:50.625+0000] {local_task_job_runner.py:120} INFO - ::group::Pre task execution logs
[2024-11-23T01:56:51.111+0000] {taskinstance.py:2076} INFO - Dependencies all met for dep_context=non-requeueable deps ti=<TaskInstance: stock_price_prediction.train_model_AGF manual__2024-11-23T01:52:07.286051+00:00 [queued]>
[2024-11-23T01:56:51.485+0000] {taskinstance.py:2076} INFO - Dependencies all met for dep_context=requeueable deps ti=<TaskInstance: stock_price_prediction.train_model_AGF manual__2024-11-23T01:52:07.286051+00:00 [queued]>
[2024-11-23T01:56:51.518+0000] {taskinstance.py:2306} INFO - Starting attempt 1 of 2
[2024-11-23T01:56:52.372+0000] {taskinstance.py:2330} INFO - Executing <Task(PythonOperator): train_model_AGF> on 2024-11-23 01:52:07.286051+00:00
[2024-11-23T01:56:52.444+0000] {logging_mixin.py:188} WARNING - /home/***/.local/lib/python3.12/site-packages/***/task/task_runner/standard_task_runner.py:61 DeprecationWarning: This process (pid=5132) is multi-threaded, use of fork() may lead to deadlocks in the child.
[2024-11-23T01:56:52.464+0000] {standard_task_runner.py:63} INFO - Started process 5139 to run task
[2024-11-23T01:56:52.448+0000] {standard_task_runner.py:90} INFO - Running: ['***', 'tasks', 'run', 'stock_price_prediction', 'train_model_AGF', 'manual__2024-11-23T01:52:07.286051+00:00', '--job-id', '548', '--raw', '--subdir', 'DAGS_FOLDER/stock_price_prediction_dag.py', '--cfg-path', '/tmp/tmpgp_j9cik']
[2024-11-23T01:56:52.481+0000] {standard_task_runner.py:91} INFO - Job 548: Subtask train_model_AGF
[2024-11-23T01:56:52.723+0000] {task_command.py:426} INFO - Running <TaskInstance: stock_price_prediction.train_model_AGF manual__2024-11-23T01:52:07.286051+00:00 [running]> on host ad983beda88b
[2024-11-23T01:56:53.001+0000] {taskinstance.py:2648} INFO - Exporting env vars: AIRFLOW_CTX_DAG_OWNER='***' AIRFLOW_CTX_DAG_ID='stock_price_prediction' AIRFLOW_CTX_TASK_ID='train_model_AGF' AIRFLOW_CTX_EXECUTION_DATE='2024-11-23T01:52:07.286051+00:00' AIRFLOW_CTX_TRY_NUMBER='1' AIRFLOW_CTX_DAG_RUN_ID='manual__2024-11-23T01:52:07.286051+00:00'
[2024-11-23T01:56:53.006+0000] {taskinstance.py:430} INFO - ::endgroup::
[2024-11-23T01:57:25.873+0000] {logging_mixin.py:188} WARNING - /home/***/.local/lib/python3.12/site-packages/keras/src/layers/convolutional/base_conv.py:107 UserWarning: Do not pass an `input_shape`/`input_dim` argument to a layer. When using Sequential models, prefer using an `Input(shape)` object as the first layer in the model instead.
[2024-11-23T01:57:26.585+0000] {logging_mixin.py:188} INFO - Epoch 1/20
[2024-11-23T01:59:08.742+0000] {logging_mixin.py:188} INFO -  4/61 ━━━━━━━━━━━━━━━━━━━━ 19:43 21s/step - loss: 0.1804
[2024-11-23T01:59:08.746+0000] {logging_mixin.py:188} INFO -  1/61 ━━━━━━━━━━━━━━━━━━━━ 16:13 16s/step - loss: 0.2543
[2024-11-23T01:59:08.747+0000] {logging_mixin.py:188} INFO -  2/61 ━━━━━━━━━━━━━━━━━━━━ 34s 587ms/step - loss: 0.2201
[2024-11-23T01:59:08.797+0000] {logging_mixin.py:188} INFO -  3/61 ━━━━━━━━━━━━━━━━━━━━ 1:39 2s/step - loss: 0.1987  
[2024-11-23T01:59:09.043+0000] {logging_mixin.py:188} INFO -  5/61 ━━━━━━━━━━━━━━━━━━━━ 20:07 22s/step - loss: 0.1646
[2024-11-23T01:59:10.050+0000] {logging_mixin.py:188} INFO -  6/61 ━━━━━━━━━━━━━━━━━━━━ 15:59 17s/step - loss: 0.1528
[2024-11-23T01:59:10.218+0000] {logging_mixin.py:188} INFO -  7/61 ━━━━━━━━━━━━━━━━━━━━ 13:06 15s/step - loss: 0.1437
[2024-11-23T01:59:10.392+0000] {logging_mixin.py:188} INFO -  8/61 ━━━━━━━━━━━━━━━━━━━━ 11:03 13s/step - loss: 0.1360
[2024-11-23T01:59:10.456+0000] {logging_mixin.py:188} INFO -  9/61 ━━━━━━━━━━━━━━━━━━━━ 9:29 11s/step - loss: 0.1292 
[2024-11-23T01:59:10.587+0000] {logging_mixin.py:188} INFO - 10/61 ━━━━━━━━━━━━━━━━━━━━ 8:17 10s/step - loss: 0.1230
[2024-11-23T01:59:10.726+0000] {logging_mixin.py:188} INFO - 12/61 ━━━━━━━━━━━━━━━━━━━━ 6:31 8s/step - loss: 0.1127 
[2024-11-23T01:59:10.798+0000] {logging_mixin.py:188} INFO - 13/61 ━━━━━━━━━━━━━━━━━━━━ 5:51 7s/step - loss: 0.1084
[2024-11-23T01:59:10.925+0000] {logging_mixin.py:188} INFO - 14/61 ━━━━━━━━━━━━━━━━━━━━ 5:18 7s/step - loss: 0.1045
[2024-11-23T01:59:11.012+0000] {logging_mixin.py:188} INFO - 15/61 ━━━━━━━━━━━━━━━━━━━━ 4:49 6s/step - loss: 0.1010
[2024-11-23T01:58:34.028+0000] {job.py:218} ERROR - Job heartbeat got an exception
Traceback (most recent call last):
  File "/home/airflow/.local/lib/python3.12/site-packages/sqlalchemy/engine/base.py", line 3371, in _wrap_pool_connect
    return fn()
           ^^^^
  File "/home/airflow/.local/lib/python3.12/site-packages/sqlalchemy/pool/base.py", line 327, in connect
    return _ConnectionFairy._checkout(self)
           ^^^^^^^^^^^^^^^^^^^^^^^^^^^^^^^^
  File "/home/airflow/.local/lib/python3.12/site-packages/sqlalchemy/pool/base.py", line 894, in _checkout
    fairy = _ConnectionRecord.checkout(pool)
            ^^^^^^^^^^^^^^^^^^^^^^^^^^^^^^^^
  File "/home/airflow/.local/lib/python3.12/site-packages/sqlalchemy/pool/base.py", line 493, in checkout
    rec = pool._do_get()
          ^^^^^^^^^^^^^^
  File "/home/airflow/.local/lib/python3.12/site-packages/sqlalchemy/pool/impl.py", line 256, in _do_get
    return self._create_connection()
           ^^^^^^^^^^^^^^^^^^^^^^^^^
  File "/home/airflow/.local/lib/python3.12/site-packages/sqlalchemy/pool/base.py", line 273, in _create_connection
    return _ConnectionRecord(self)
           ^^^^^^^^^^^^^^^^^^^^^^^
  File "/home/airflow/.local/lib/python3.12/site-packages/sqlalchemy/pool/base.py", line 388, in __init__
    self.__connect()
  File "/home/airflow/.local/lib/python3.12/site-packages/sqlalchemy/pool/base.py", line 690, in __connect
    with util.safe_reraise():
  File "/home/airflow/.local/lib/python3.12/site-packages/sqlalchemy/util/langhelpers.py", line 70, in __exit__
    compat.raise_(
  File "/home/airflow/.local/lib/python3.12/site-packages/sqlalchemy/util/compat.py", line 211, in raise_
    raise exception
  File "/home/airflow/.local/lib/python3.12/site-packages/sqlalchemy/pool/base.py", line 686, in __connect
    self.dbapi_connection = connection = pool._invoke_creator(self)
                                         ^^^^^^^^^^^^^^^^^^^^^^^^^^
  File "/home/airflow/.local/lib/python3.12/site-packages/sqlalchemy/engine/create.py", line 574, in connect
    return dialect.connect(*cargs, **cparams)
           ^^^^^^^^^^^^^^^^^^^^^^^^^^^^^^^^^^
  File "/home/airflow/.local/lib/python3.12/site-packages/sqlalchemy/engine/default.py", line 598, in connect
    return self.dbapi.connect(*cargs, **cparams)
           ^^^^^^^^^^^^^^^^^^^^^^^^^^^^^^^^^^^^^
  File "/home/airflow/.local/lib/python3.12/site-packages/psycopg2/__init__.py", line 122, in connect
    conn = _connect(dsn, connection_factory=connection_factory, **kwasync)
           ^^^^^^^^^^^^^^^^^^^^^^^^^^^^^^^^^^^^^^^^^^^^^^^^^^^^^^^^^^^^^^^
psycopg2.OperationalError: could not translate host name "postgres" to address: Temporary failure in name resolution


The above exception was the direct cause of the following exception:

Traceback (most recent call last):
  File "/home/airflow/.local/lib/python3.12/site-packages/airflow/jobs/job.py", line 192, in heartbeat
    self._merge_from(Job._fetch_from_db(self, session))
                     ^^^^^^^^^^^^^^^^^^^^^^^^^^^^^^^^^
  File "/home/airflow/.local/lib/python3.12/site-packages/airflow/api_internal/internal_api_call.py", line 115, in wrapper
    return func(*args, **kwargs)
           ^^^^^^^^^^^^^^^^^^^^^
  File "/home/airflow/.local/lib/python3.12/site-packages/airflow/utils/session.py", line 76, in wrapper
    return func(*args, **kwargs)
           ^^^^^^^^^^^^^^^^^^^^^
  File "/home/airflow/.local/lib/python3.12/site-packages/airflow/utils/retries.py", line 89, in wrapped_function
    for attempt in run_with_db_retries(max_retries=retries, logger=logger, **retry_kwargs):
  File "/home/airflow/.local/lib/python3.12/site-packages/tenacity/__init__.py", line 347, in __iter__
    do = self.iter(retry_state=retry_state)
         ^^^^^^^^^^^^^^^^^^^^^^^^^^^^^^^^^^
  File "/home/airflow/.local/lib/python3.12/site-packages/tenacity/__init__.py", line 325, in iter
    raise retry_exc.reraise()
          ^^^^^^^^^^^^^^^^^^^
  File "/home/airflow/.local/lib/python3.12/site-packages/tenacity/__init__.py", line 158, in reraise
    raise self.last_attempt.result()
          ^^^^^^^^^^^^^^^^^^^^^^^^^^
  File "/usr/local/lib/python3.12/concurrent/futures/_base.py", line 449, in result
    return self.__get_result()
           ^^^^^^^^^^^^^^^^^^^
  File "/usr/local/lib/python3.12/concurrent/futures/_base.py", line 401, in __get_result
    raise self._exception
  File "/home/airflow/.local/lib/python3.12/site-packages/airflow/utils/retries.py", line 98, in wrapped_function
    return func(*args, **kwargs)
           ^^^^^^^^^^^^^^^^^^^^^
  File "/home/airflow/.local/lib/python3.12/site-packages/airflow/jobs/job.py", line 316, in _fetch_from_db
    session.merge(job)
  File "/home/airflow/.local/lib/python3.12/site-packages/sqlalchemy/orm/session.py", line 3056, in merge
    return self._merge(
           ^^^^^^^^^^^^
  File "/home/airflow/.local/lib/python3.12/site-packages/sqlalchemy/orm/session.py", line 3136, in _merge
    merged = self.get(
             ^^^^^^^^^
  File "/home/airflow/.local/lib/python3.12/site-packages/sqlalchemy/orm/session.py", line 2853, in get
    return self._get_impl(
           ^^^^^^^^^^^^^^^
  File "/home/airflow/.local/lib/python3.12/site-packages/sqlalchemy/orm/session.py", line 2975, in _get_impl
    return db_load_fn(
           ^^^^^^^^^^^
  File "/home/airflow/.local/lib/python3.12/site-packages/sqlalchemy/orm/loading.py", line 530, in load_on_pk_identity
    session.execute(
  File "/home/airflow/.local/lib/python3.12/site-packages/sqlalchemy/orm/session.py", line 1716, in execute
    conn = self._connection_for_bind(bind)
           ^^^^^^^^^^^^^^^^^^^^^^^^^^^^^^^
  File "/home/airflow/.local/lib/python3.12/site-packages/sqlalchemy/orm/session.py", line 1555, in _connection_for_bind
    return self._transaction._connection_for_bind(
           ^^^^^^^^^^^^^^^^^^^^^^^^^^^^^^^^^^^^^^^
  File "/home/airflow/.local/lib/python3.12/site-packages/sqlalchemy/orm/session.py", line 750, in _connection_for_bind
    conn = bind.connect()
           ^^^^^^^^^^^^^^
  File "/home/airflow/.local/lib/python3.12/site-packages/sqlalchemy/future/engine.py", line 412, in connect
    return super(Engine, self).connect()
           ^^^^^^^^^^^^^^^^^^^^^^^^^^^^^
  File "/home/airflow/.local/lib/python3.12/site-packages/sqlalchemy/engine/base.py", line 3325, in connect
    return self._connection_cls(self, close_with_result=close_with_result)
           ^^^^^^^^^^^^^^^^^^^^^^^^^^^^^^^^^^^^^^^^^^^^^^^^^^^^^^^^^^^^^^^
  File "/home/airflow/.local/lib/python3.12/site-packages/sqlalchemy/engine/base.py", line 96, in __init__
    else engine.raw_connection()
         ^^^^^^^^^^^^^^^^^^^^^^^
  File "/home/airflow/.local/lib/python3.12/site-packages/sqlalchemy/engine/base.py", line 3404, in raw_connection
    return self._wrap_pool_connect(self.pool.connect, _connection)
           ^^^^^^^^^^^^^^^^^^^^^^^^^^^^^^^^^^^^^^^^^^^^^^^^^^^^^^^
  File "/home/airflow/.local/lib/python3.12/site-packages/sqlalchemy/engine/base.py", line 3374, in _wrap_pool_connect
    Connection._handle_dbapi_exception_noconnection(
  File "/home/airflow/.local/lib/python3.12/site-packages/sqlalchemy/engine/base.py", line 2208, in _handle_dbapi_exception_noconnection
    util.raise_(
  File "/home/airflow/.local/lib/python3.12/site-packages/sqlalchemy/util/compat.py", line 211, in raise_
    raise exception
  File "/home/airflow/.local/lib/python3.12/site-packages/sqlalchemy/engine/base.py", line 3371, in _wrap_pool_connect
    return fn()
           ^^^^
  File "/home/airflow/.local/lib/python3.12/site-packages/sqlalchemy/pool/base.py", line 327, in connect
    return _ConnectionFairy._checkout(self)
           ^^^^^^^^^^^^^^^^^^^^^^^^^^^^^^^^
  File "/home/airflow/.local/lib/python3.12/site-packages/sqlalchemy/pool/base.py", line 894, in _checkout
    fairy = _ConnectionRecord.checkout(pool)
            ^^^^^^^^^^^^^^^^^^^^^^^^^^^^^^^^
  File "/home/airflow/.local/lib/python3.12/site-packages/sqlalchemy/pool/base.py", line 493, in checkout
    rec = pool._do_get()
          ^^^^^^^^^^^^^^
  File "/home/airflow/.local/lib/python3.12/site-packages/sqlalchemy/pool/impl.py", line 256, in _do_get
    return self._create_connection()
           ^^^^^^^^^^^^^^^^^^^^^^^^^
  File "/home/airflow/.local/lib/python3.12/site-packages/sqlalchemy/pool/base.py", line 273, in _create_connection
    return _ConnectionRecord(self)
           ^^^^^^^^^^^^^^^^^^^^^^^
  File "/home/airflow/.local/lib/python3.12/site-packages/sqlalchemy/pool/base.py", line 388, in __init__
    self.__connect()
  File "/home/airflow/.local/lib/python3.12/site-packages/sqlalchemy/pool/base.py", line 690, in __connect
    with util.safe_reraise():
  File "/home/airflow/.local/lib/python3.12/site-packages/sqlalchemy/util/langhelpers.py", line 70, in __exit__
    compat.raise_(
  File "/home/airflow/.local/lib/python3.12/site-packages/sqlalchemy/util/compat.py", line 211, in raise_
    raise exception
  File "/home/airflow/.local/lib/python3.12/site-packages/sqlalchemy/pool/base.py", line 686, in __connect
    self.dbapi_connection = connection = pool._invoke_creator(self)
                                         ^^^^^^^^^^^^^^^^^^^^^^^^^^
  File "/home/airflow/.local/lib/python3.12/site-packages/sqlalchemy/engine/create.py", line 574, in connect
    return dialect.connect(*cargs, **cparams)
           ^^^^^^^^^^^^^^^^^^^^^^^^^^^^^^^^^^
  File "/home/airflow/.local/lib/python3.12/site-packages/sqlalchemy/engine/default.py", line 598, in connect
    return self.dbapi.connect(*cargs, **cparams)
           ^^^^^^^^^^^^^^^^^^^^^^^^^^^^^^^^^^^^^
  File "/home/airflow/.local/lib/python3.12/site-packages/psycopg2/__init__.py", line 122, in connect
    conn = _connect(dsn, connection_factory=connection_factory, **kwasync)
           ^^^^^^^^^^^^^^^^^^^^^^^^^^^^^^^^^^^^^^^^^^^^^^^^^^^^^^^^^^^^^^^
sqlalchemy.exc.OperationalError: (psycopg2.OperationalError) could not translate host name "postgres" to address: Temporary failure in name resolution

(Background on this error at: https://sqlalche.me/e/14/e3q8)
[2024-11-23T01:59:11.128+0000] {logging_mixin.py:188} INFO - 16/61 ━━━━━━━━━━━━━━━━━━━━ 4:24 6s/step - loss: 0.0978
[2024-11-23T01:59:11.121+0000] {job.py:226} ERROR - Job heartbeat failed with error. Scheduler is in unhealthy state
[2024-11-23T01:59:11.214+0000] {logging_mixin.py:188} INFO - 18/61 ━━━━━━━━━━━━━━━━━━━━ 3:43 5s/step - loss: 0.0920
[2024-11-23T01:59:11.312+0000] {logging_mixin.py:188} INFO - 20/61 ━━━━━━━━━━━━━━━━━━━━ 3:10 5s/step - loss: 0.0870
[2024-11-23T01:59:11.740+0000] {logging_mixin.py:188} INFO - 21/61 ━━━━━━━━━━━━━━━━━━━━ 2:57 4s/step - loss: 0.0847
[2024-11-23T01:59:12.675+0000] {logging_mixin.py:188} INFO - 22/61 ━━━━━━━━━━━━━━━━━━━━ 2:46 4s/step - loss: 0.0826
[2024-11-23T01:59:12.759+0000] {logging_mixin.py:188} INFO - 23/61 ━━━━━━━━━━━━━━━━━━━━ 2:35 4s/step - loss: 0.0806
[2024-11-23T01:59:12.811+0000] {logging_mixin.py:188} INFO - 24/61 ━━━━━━━━━━━━━━━━━━━━ 2:24 4s/step - loss: 0.0788
[2024-11-23T01:59:12.913+0000] {logging_mixin.py:188} INFO - 26/61 ━━━━━━━━━━━━━━━━━━━━ 2:06 4s/step - loss: 0.0753
[2024-11-23T01:59:12.966+0000] {logging_mixin.py:188} INFO - 27/61 ━━━━━━━━━━━━━━━━━━━━ 1:57 3s/step - loss: 0.0737
[2024-11-23T01:59:14.091+0000] {logging_mixin.py:188} INFO - 29/61 ━━━━━━━━━━━━━━━━━━━━ 1:43 3s/step - loss: 0.0708
[2024-11-23T01:59:15.182+0000] {logging_mixin.py:188} INFO - 30/61 ━━━━━━━━━━━━━━━━━━━━ 1:38 3s/step - loss: 0.0694
[2024-11-23T01:59:17.639+0000] {logging_mixin.py:188} INFO - 31/61 ━━━━━━━━━━━━━━━━━━━━ 1:33 3s/step - loss: 0.0681
[2024-11-23T01:59:18.059+0000] {logging_mixin.py:188} INFO - 32/61 ━━━━━━━━━━━━━━━━━━━━ 1:28 3s/step - loss: 0.0669
[2024-11-23T02:00:45.827+0000] {job.py:226} ERROR - Job heartbeat failed with error. Scheduler is in unhealthy state
[2024-11-23T02:01:19.421+0000] {logging_mixin.py:188} INFO - 33/61 ━━━━━━━━━━━━━━━━━━━━ 1:26 3s/step - loss: 0.0657
[2024-11-23T02:01:19.671+0000] {logging_mixin.py:188} INFO - 34/61 ━━━━━━━━━━━━━━━━━━━━ 2:57 7s/step - loss: 0.0645
[2024-11-23T02:01:19.787+0000] {logging_mixin.py:188} INFO - 35/61 ━━━━━━━━━━━━━━━━━━━━ 2:45 6s/step - loss: 0.0634
